Workbook

Sheet Balance
A1: Capital One — Average Balance by line item ($mm)
A2: Average balance over the quarter. Actuals through Q2:25; Q3:25–Q2:26 forecast from the macro-driven monthly schedule.
A4: Line item (as disclosed) | B4: 2023-03-31 | C4: 2023-06-30 | D4: 2023-09-30 | E4: 2023-12-31 (D) | F4: 2024-03-31 | G4: 2024-06-30 | H4: 2024-09-30 | I4: 2024-12-31 (D) | J4: 2025-03-31 | K4: 2025-06-30 | L4: 2025-09-30 (F) | M4: 2025-12-31 (F) | N4: 2026-03-31 (F) | O4: 2026-06-30 (F)
A5: INTEREST-EARNING ASSETS
A6: Credit card | B6: 134669 | C6: 138762 | D6: 144053 | E6: 149112 | F6: 150049 | G6: 150866 | H6: 154160 | I6: 157360 | J6: 156408 | K6: 209693 | L6: =SUM('Monthly EOP Balance'!AF6:'Monthly EOP Balance'!AI6)/4 -> 243413.58 | M6: =SUM('Monthly EOP Balance'!AI6:'Monthly EOP Balance'!AL6)/4 -> 243537.96 | N6: =SUM('Monthly EOP Balance'!AL6:'Monthly EOP Balance'!AO6)/4 -> 243662.34 | O6: =SUM('Monthly EOP Balance'!AO6:'Monthly EOP Balance'!AR6)/4 -> 243786.72
A7: Consumer banking | B7: 79000 | C7: 77699 | D7: 77154 | E7: 76224 | F7: 75091 | G7: 75386 | H7: 76182 | I7: 77231 | J7: 78480 | K7: 80095 | L7: =SUM('Monthly EOP Balance'!AF7:'Monthly EOP Balance'!AI7)/4 -> 92926.536 | M7: =SUM('Monthly EOP Balance'!AI7:'Monthly EOP Balance'!AL7)/4 -> 92877.078 | N7: =SUM('Monthly EOP Balance'!AL7:'Monthly EOP Balance'!AO7)/4 -> 92827.619 | O7: =SUM('Monthly EOP Balance'!AO7:'Monthly EOP Balance'!AR7)/4 -> 92778.16
A8: Commercial banking | B8: 94446 | C8: 93874 | D8: 92254 | E8: 91385 | F8: 90423 | G8: 89571 | H8: 88373 | I8: 87672 | J8: 87884 | K8: 88749 | L8: =SUM('Monthly EOP Balance'!AF8:'Monthly EOP Balance'!AI8)/4 -> 103020.66 | M8: =SUM('Monthly EOP Balance'!AI8:'Monthly EOP Balance'!AL8)/4 -> 103073.31 | N8: =SUM('Monthly EOP Balance'!AL8:'Monthly EOP Balance'!AO8)/4 -> 103125.95 | O8: =SUM('Monthly EOP Balance'!AO8:'Monthly EOP Balance'!AR8)/4 -> 103178.59
A9: Total loans (incl. HFS) | B9: 308115 | C9: 310335 | D9: 313461 | E9: 316721 | F9: 315563 | G9: 315823 | H9: 318715 | I9: 322263 | J9: 322772 | K9: 378537 | L9: =SUM('Monthly EOP Balance'!AF9:'Monthly EOP Balance'!AI9)/4 -> 439360.78 | M9: =SUM('Monthly EOP Balance'!AI9:'Monthly EOP Balance'!AL9)/4 -> 439488.34 | N9: =SUM('Monthly EOP Balance'!AL9:'Monthly EOP Balance'!AO9)/4 -> 439615.91 | O9: =SUM('Monthly EOP Balance'!AO9:'Monthly EOP Balance'!AR9)/4 -> 439743.47
A10: Investment securities | B10: 89960 | C10: 89994 | D10: 87845 | E10: 88643 | F10: 88581 | G10: 89501 | H10: 90644 | I10: 92260 | J10: 92659 | K10: 93024 | L10: =SUM('Monthly EOP Balance'!AF10:'Monthly EOP Balance'!AI10)/4 -> 87196 | M10: =SUM('Monthly EOP Balance'!AI10:'Monthly EOP Balance'!AL10)/4 -> 87196 | N10: =SUM('Monthly EOP Balance'!AL10:'Monthly EOP Balance'!AO10)/4 -> 87196 | O10: =SUM('Monthly EOP Balance'!AO10:'Monthly EOP Balance'!AR10)/4 -> 87196
A11: Cash equivalents and other | B11: 37124 | C11: 38810 | D11: 42226 | E11: 41625 | F11: 43659 | G11: 45584 | H11: 45125 | I11: 46167 | J11: 47340 | K11: 53368 | L11: =SUM('Monthly EOP Balance'!AF11:'Monthly EOP Balance'!AI11)/4 -> 61593.737 | M11: =SUM('Monthly EOP Balance'!AI11:'Monthly EOP Balance'!AL11)/4 -> 61625.21 | N11: =SUM('Monthly EOP Balance'!AL11:'Monthly EOP Balance'!AO11)/4 -> 61656.683 | O11: =SUM('Monthly EOP Balance'!AO11:'Monthly EOP Balance'!AR11)/4 -> 61688.156
A12: Total interest-earning assets | B12: 435199 | C12: 439139 | D12: 443532 | E12: 446989 | F12: 447803 | G12: 450908 | H12: 454484 | I12: 460690 | J12: 462771 | K12: 524929 | L12: =SUM('Monthly EOP Balance'!AF12:'Monthly EOP Balance'!AI12)/4 -> 588150.52 | M12: =SUM('Monthly EOP Balance'!AI12:'Monthly EOP Balance'!AL12)/4 -> 588309.55 | N12: =SUM('Monthly EOP Balance'!AL12:'Monthly EOP Balance'!AO12)/4 -> 588468.59 | O12: =SUM('Monthly EOP Balance'!AO12:'Monthly EOP Balance'!AR12)/4 -> 588627.63
A14: INTEREST-BEARING LIABILITIES
A15: Interest-bearing deposits | B15: 308788 | C15: 313207 | D15: 316032 | E15: 316842 | F15: 318450 | G15: 322581 | H15: 324509 | I15: 331620 | J15: 337840 | K15: 387139 | L15: =SUM('Monthly EOP Balance'!AF15:'Monthly EOP Balance'!AI15)/4 -> 440343.5 | M15: =SUM('Monthly EOP Balance'!AI15:'Monthly EOP Balance'!AL15)/4 -> 440568.51 | N15: =SUM('Monthly EOP Balance'!AL15:'Monthly EOP Balance'!AO15)/4 -> 440793.52 | O15: =SUM('Monthly EOP Balance'!AO15:'Monthly EOP Balance'!AR15)/4 -> 441018.53
A16: Securitized debt obligations | B16: 17251 | C16: 17771 | D16: 17649 | E16: 18026 | F16: 17836 | G16: 17452 | H16: 15833 | I16: 14920 | J16: 13731 | K16: 13043 | L16: =SUM('Monthly EOP Balance'!AF16:'Monthly EOP Balance'!AI16)/4 -> 14639.71 | M16: =SUM('Monthly EOP Balance'!AI16:'Monthly EOP Balance'!AL16)/4 -> 14421.211 | N16: =SUM('Monthly EOP Balance'!AL16:'Monthly EOP Balance'!AO16)/4 -> 14205.973 | O16: =SUM('Monthly EOP Balance'!AO16:'Monthly EOP Balance'!AR16)/4 -> 13993.947
A17: Senior and subordinated notes | B17: 30136 | C17: 30161 | D17: 31522 | E17: 32603 | F17: 32211 | G17: 30978 | H17: 32041 | I17: 30884 | J17: 30331 | K17: 32872 | L17: =SUM('Monthly EOP Balance'!AF17:'Monthly EOP Balance'!AI17)/4 -> 37174.033 | M17: =SUM('Monthly EOP Balance'!AI17:'Monthly EOP Balance'!AL17)/4 -> 37174.033 | N17: =SUM('Monthly EOP Balance'!AL17:'Monthly EOP Balance'!AO17)/4 -> 37174.033 | O17: =SUM('Monthly EOP Balance'!AO17:'Monthly EOP Balance'!AR17)/4 -> 37174.033
A18: Other borrowings | B18: 2335 | C18: 2419 | D18: 2473 | E18: 2346 | F18: 2373 | G18: 2502 | H18: 2389 | I18: 2430 | J18: 2312 | K18: 2872 | L18: =SUM('Monthly EOP Balance'!AF18:'Monthly EOP Balance'!AI18)/4 -> 1302 | M18: =SUM('Monthly EOP Balance'!AI18:'Monthly EOP Balance'!AL18)/4 -> 1302 | N18: =SUM('Monthly EOP Balance'!AL18:'Monthly EOP Balance'!AO18)/4 -> 1302 | O18: =SUM('Monthly EOP Balance'!AO18:'Monthly EOP Balance'!AR18)/4 -> 1302
A19: Total interest-bearing liabilities | B19: 358510 | C19: 363558 | D19: 367676 | E19: 369817 | F19: 370870 | G19: 373513 | H19: 374772 | I19: 379854 | J19: 384214 | K19: 435926 | L19: =SUM('Monthly EOP Balance'!AF19:'Monthly EOP Balance'!AI19)/4 -> 493459.25 | M19: =SUM('Monthly EOP Balance'!AI19:'Monthly EOP Balance'!AL19)/4 -> 493465.76 | N19: =SUM('Monthly EOP Balance'!AL19:'Monthly EOP Balance'!AO19)/4 -> 493475.52 | O19: =SUM('Monthly EOP Balance'!AO19:'Monthly EOP Balance'!AR19)/4 -> 493488.51
A21: Net earning assets (assets − liabilities) | B21: =B12-B19 -> 76689 | C21: =C12-C19 -> 75581 | D21: =D12-D19 -> 75856 | E21: =E12-E19 -> 77172 | F21: =F12-F19 -> 76933 | G21: =G12-G19 -> 77395 | H21: =H12-H19 -> 79712 | I21: =I12-I19 -> 80836 | ... K21: =K12-K19 -> 89003 | L21: =SUM('Monthly EOP Balance'!AF21:'Monthly EOP Balance'!AI21)/4 -> 94691.271 | M21: =SUM('Monthly EOP Balance'!AI21:'Monthly EOP Balance'!AL21)/4 -> 94843.799 | N21: =SUM('Monthly EOP Balance'!AL21:'Monthly EOP Balance'!AO21)/4 -> 94993.066 | O21: =SUM('Monthly EOP Balance'!AO21:'Monthly EOP Balance'!AR21)/4 -> 95139.121

Sheet Rate
A1: Capital One — Average Yield / Rate by line item (annualised)
A2: Annualised yield on assets and cost of funds on liabilities. Actuals through Q2:25; forecast rates retain June 2025 benchmark spreads or betas.
A4: Line item (as disclosed) | B4: 2023-03-31 | C4: 2023-06-30 | D4: 2023-09-30 | E4: 2023-12-31 (D) | F4: 2024-03-31 | G4: 2024-06-30 | H4: 2024-09-30 | I4: 2024-12-31 (D) | J4: 2025-03-31 | K4: 2025-06-30 | L4: 2025-09-30 (F) | M4: 2025-12-31 (F) | N4: 2026-03-31 (F) | O4: 2026-06-30 (F)
A5: INTEREST-EARNING ASSETS
A6: Credit card | B6: 0.1798 | C6: 0.1817 | D6: 0.1902 | E6: 0.1894 | F6: 0.1884 | G6: 0.1879 | H6: 0.1966 | I6: 0.1905 | J6: 0.1854 | K6: 0.1794 | L6: =IF(Balance!L6=0,"",'Net Interest Income'!L6*4/Balance!L6) -> 0.17615904 | M6: =IF(Balance!M6=0,"",'Net Interest Income'!M6*4/Balance!M6) -> 0.17528404 | N6: =IF(Balance!N6=0,"",'Net Interest Income'!N6*4/Balance!N6) -> 0.17440904 | O6: =IF(Balance!O6=0,"",'Net Interest Income'!O6*4/Balance!O6) -> 0.17353404
A7: Consumer banking | B7: 0.074 | C7: 0.0765 | D7: 0.0797 | E7: 0.0817 | F7: 0.0833 | G7: 0.0854 | H7: 0.0888 | I7: 0.0904 | J7: 0.0903 | K7: 0.093 | L7: =IF(Balance!L7=0,"",'Net Interest Income'!L7*4/Balance!L7) -> 0.095173115 | M7: =IF(Balance!M7=0,"",'Net Interest Income'!M7*4/Balance!M7) -> 0.095123115 | N7: =IF(Balance!N7=0,"",'Net Interest Income'!N7*4/Balance!N7) -> 0.095073115 | O7: =IF(Balance!O7=0,"",'Net Interest Income'!O7*4/Balance!O7) -> 0.095023115
A8: Commercial banking | B8: 0.063 | C8: 0.0674 | D8: 0.0712 | E8: 0.0724 | F8: 0.0713 | G8: 0.0722 | H8: 0.0724 | I8: 0.0672 | J8: 0.0629 | K8: 0.064 | L8: =IF(Balance!L8=0,"",'Net Interest Income'!L8*4/Balance!L8) -> 0.065225042 | M8: =IF(Balance!M8=0,"",'Net Interest Income'!M8*4/Balance!M8) -> 0.064475042 | N8: =IF(Balance!N8=0,"",'Net Interest Income'!N8*4/Balance!N8) -> 0.063725042 | O8: =IF(Balance!O8=0,"",'Net Interest Income'!O8*4/Balance!O8) -> 0.062975042
A9: Total loans (incl. HFS) | B9: 0.1132 | C9: 0.1167 | D9: 0.1237 | E9: 0.1255 | F9: 0.1257 | G9: 0.1266 | H9: 0.1324 | I9: 0.1295 | J9: 0.1259 | K9: 0.1315 | L9: =IF(Balance!L9=0,"",'Net Interest Income'!L9*4/Balance!L9) -> 0.13301856 | M9: =IF(Balance!M9=0,"",'Net Interest Income'!M9*4/Balance!M9) -> 0.13235557 | N9: =IF(Balance!N9=0,"",'Net Interest Income'!N9*4/Balance!N9) -> 0.1316923 | O9: =IF(Balance!O9=0,"",'Net Interest Income'!O9*4/Balance!O9) -> 0.13102876
A10: Investment securities | B10: 0.0273 | C10: 0.0284 | D10: 0.0286 | E10: 0.0302 | F10: 0.031 | G10: 0.0313 | H10: 0.0324 | I10: 0.0326 | J10: 0.0332 | K10: 0.0337 | L10: =IF(Balance!L10=0,"",'Net Interest Income'!L10*4/Balance!L10) -> 0.031892018 | M10: =IF(Balance!M10=0,"",'Net Interest Income'!M10*4/Balance!M10) -> 0.030442018 | N10: =IF(Balance!N10=0,"",'Net Interest Income'!N10*4/Balance!N10) -> 0.028992018 | O10: =IF(Balance!O10=0,"",'Net Interest Income'!O10*4/Balance!O10) -> 0.027542018
A11: Cash equivalents and other | B11: 0.0449 | C11: 0.0484 | D11: 0.0521 | E11: 0.0521 | F11: 0.0521 | G11: 0.0516 | H11: 0.0514 | I11: 0.0459 | J11: 0.0414 | K11: 0.0446 | L11: =IF(Balance!L11=0,"",'Net Interest Income'!L11*4/Balance!L11) -> 0.044632572 | M11: =IF(Balance!M11=0,"",'Net Interest Income'!M11*4/Balance!M11) -> 0.043882572 | N11: =IF(Balance!N11=0,"",'Net Interest Income'!N11*4/Balance!N11) -> 0.043132572 | O11: =IF(Balance!O11=0,"",'Net Interest Income'!O11*4/Balance!O11) -> 0.042382572
A12: Total interest-earning assets | B12: 0.0896 | C12: 0.0926 | D12: 0.0981 | E12: 0.0997 | F12: 0.0998 | G12: 0.1001 | H12: 0.1044 | I12: 0.1017 | J12: 0.0987 | K12: 0.1054 | L12: =IF(Balance!L12=0,"",'Net Interest Income'!L12*4/Balance!L12) -> 0.10876991 | M12: =IF(Balance!M12=0,"",'Net Interest Income'!M12*4/Balance!M12) -> 0.10798299 | N12: =IF(Balance!N12=0,"",'Net Interest Income'!N12*4/Balance!N12) -> 0.10719592 | O12: =IF(Balance!O12=0,"",'Net Interest Income'!O12*4/Balance!O12) -> 0.10640869
A14: INTEREST-BEARING LIABILITIES
A15: Interest-bearing deposits | B15: 0.024 | C15: 0.0291 | D15: 0.033 | E15: 0.0347 | F15: 0.0353 | G15: 0.0356 | H15: 0.0363 | I15: 0.0345 | J15: 0.0322 | K15: 0.0322 | L15: =IF(Balance!L15=0,"",'Net Interest Income'!L15*4/Balance!L15) -> 0.031959386 | M15: =IF(Balance!M15=0,"",'Net Interest Income'!M15*4/Balance!M15) -> 0.03139935 | N15: =IF(Balance!N15=0,"",'Net Interest Income'!N15*4/Balance!N15) -> 0.030839314 | O15: =IF(Balance!O15=0,"",'Net Interest Income'!O15*4/Balance!O15) -> 0.030279277
A16: Securitized debt obligations | B16: 0.049 | C16: 0.0531 | D16: 0.0563 | E16: 0.0584 | F16: 0.0585 | G16: 0.0591 | H16: 0.0593 | I16: 0.055 | J16: 0.0511 | K16: 0.0506 | L16: =IF(Balance!L16=0,"",'Net Interest Income'!L16*4/Balance!L16) -> 0.050314841 | M16: =IF(Balance!M16=0,"",'Net Interest Income'!M16*4/Balance!M16) -> 0.048864847 | N16: =IF(Balance!N16=0,"",'Net Interest Income'!N16*4/Balance!N16) -> 0.047414853 | O16: =IF(Balance!O16=0,"",'Net Interest Income'!O16*4/Balance!O16) -> 0.045964859
A17: Senior and subordinated notes | B17: 0.0649 | C17: 0.07 | D17: 0.0736 | E17: 0.0746 | F17: 0.0752 | G17: 0.0764 | H17: 0.0743 | I17: 0.0699 | J17: 0.0666 | K17: 0.0651 | L17: =IF(Balance!L17=0,"",'Net Interest Income'!L17*4/Balance!L17) -> 0.064401724 | M17: =IF(Balance!M17=0,"",'Net Interest Income'!M17*4/Balance!M17) -> 0.063456224 | N17: =IF(Balance!N17=0,"",'Net Interest Income'!N17*4/Balance!N17) -> 0.062510724 | O17: =IF(Balance!O17=0,"",'Net Interest Income'!O17*4/Balance!O17) -> 0.061565224
A18: Other borrowings | B18: 0.0208 | C18: 0.0195 | D18: 0.0179 | E18: 0.0171 | F18: 0.0178 | G18: 0.0173 | H18: 0.015 | I18: 0.0198 | J18: 0.0157 | K18: 0.0185 | L18: =IF(Balance!L18=0,"",'Net Interest Income'!L18*4/Balance!L18) -> 0.015442304 | M18: =IF(Balance!M18=0,"",'Net Interest Income'!M18*4/Balance!M18) -> 0.014692304 | N18: =IF(Balance!N18=0,"",'Net Interest Income'!N18*4/Balance!N18) -> 0.013942304 | O18: =IF(Balance!O18=0,"",'Net Interest Income'!O18*4/Balance!O18) -> 0.013192304
A19: Total interest-bearing liabilities | B19: 0.0287 | C19: 0.0336 | D19: 0.0375 | E19: 0.0392 | F19: 0.0398 | G19: 0.04 | H19: 0.0404 | I19: 0.0381 | J19: 0.0354 | K19: 0.0352 | L19: =IF(Balance!L19=0,"",'Net Interest Income'!L19*4/Balance!L19) -> 0.034904363 | M19: =IF(Balance!M19=0,"",'Net Interest Income'!M19*4/Balance!M19) -> 0.034280612 | N19: =IF(Balance!N19=0,"",'Net Interest Income'!N19*4/Balance!N19) -> 0.033657743 | O19: =IF(Balance!O19=0,"",'Net Interest Income'!O19*4/Balance!O19) -> 0.033035736
A21: Net interest spread (asset yield − funding cost) | B21: =B12-B19 -> 0.0609 | C21: =C12-C19 -> 0.059 | D21: =D12-D19 -> 0.0606 | E21: =E12-E19 -> 0.0605 | F21: =F12-F19 -> 0.06 | G21: =G12-G19 -> 0.0601 | H21: =H12-H19 -> 0.064 | I21: =I12-I19 -> 0.0636 | ... O21: =O12-O19 -> 0.073372956
A22: Net interest margin (NII / avg earning assets) | B22: =IFERROR(('Net Interest Income'!B21*4)/Balance!B12,"") -> 0.066047946 | C22: =IFERROR(('Net Interest Income'!C21*4)/Balance!C12,"") -> 0.064790419 | D22: =IFERROR(('Net Interest Income'!D21*4)/Balance!D12,"") -> 0.066944437 | E22: =IFERROR(('Net Interest Income'!E21*4)/Balance!E12,"") -> 0.067285772 | F22: =IFERROR(('Net Interest Income'!F21*4)/Balance!F12,"") -> 0.066886555 | G22: =IFERROR(('Net Interest Income'!G21*4)/Balance!G12,"") -> 0.066940485 | H22: =IFERROR(('Net Interest Income'!H21*4)/Balance!H12,"") -> 0.07107841 | I22: =IFERROR(('Net Interest Income'!I21*4)/Balance!I12,"") -> 0.070311923 | ... K22: =IFERROR(('Net Interest Income'!K21*4)/Balance!K12,"") -> 0.076162681 | L22: ='Net Interest Income'!L21*4/Balance!L12 -> 0.079485095 | M22: ='Net Interest Income'!M21*4/Balance!M12 -> 0.079228896 | N22: ='Net Interest Income'!N21*4/Balance!N12 -> 0.078971347 | O22: ='Net Interest Income'!O21*4/Balance!O12 -> 0.07871248

Sheet Net Interest Income
A1: Capital One — Interest Income / Expense by line item ($mm, quarterly)
A2: Interest income on assets and interest expense on liabilities. Actuals through Q2:25; forecast quarters sum the macro-driven monthly schedule.
A4: Line item (as disclosed) | B4: 2023-03-31 | C4: 2023-06-30 | D4: 2023-09-30 | E4: 2023-12-31 (D) | F4: 2024-03-31 | G4: 2024-06-30 | H4: 2024-09-30 | I4: 2024-12-31 (D) | J4: 2025-03-31 | K4: 2025-06-30 | L4: 2025-09-30 (F) | M4: 2025-12-31 (F) | N4: 2026-03-31 (F) | O4: 2026-06-30 (F)
A5: INTEREST-EARNING ASSETS
A6: Credit card | B6: 6053 | C6: 6302 | D6: 6850 | E6: 7062 | F6: 7067 | G6: 7088 | H6: 7578 | I6: 7493 | J6: 7248 | K6: 9407 | L6: =SUM('Monthly NII'!AF6:'Monthly NII'!AH6) -> 10719.876 | M6: =SUM('Monthly NII'!AI6:'Monthly NII'!AK6) -> 10672.079 | N6: =SUM('Monthly NII'!AL6:'Monthly NII'!AN6) -> 10624.229 | O6: =SUM('Monthly NII'!AO6:'Monthly NII'!AQ6) -> 10576.323
A7: Consumer banking | B7: 1461 | C7: 1486 | D7: 1537 | E7: 1557 | F7: 1564 | G7: 1611 | H7: 1692 | I7: 1745 | J7: 1773 | K7: 1861 | L7: =SUM('Monthly NII'!AF7:'Monthly NII'!AH7) -> 2211.027 | M7: =SUM('Monthly NII'!AI7:'Monthly NII'!AK7) -> 2208.6892 | N7: =SUM('Monthly NII'!AL7:'Monthly NII'!AN7) -> 2206.3527 | O7: =SUM('Monthly NII'!AO7:'Monthly NII'!AQ7) -> 2204.0174
A8: Commercial banking | B8: 1488 | C8: 1580 | D8: 1642 | E8: 1653 | F8: 1612 | G8: 1616 | H8: 1601 | I8: 1472 | J8: 1382 | K8: 1421 | L8: =SUM('Monthly NII'!AF8:'Monthly NII'!AH8) -> 1679.8818 | M8: =SUM('Monthly NII'!AI8:'Monthly NII'!AK8) -> 1661.4139 | N8: =SUM('Monthly NII'!AL8:'Monthly NII'!AN8) -> 1642.9263 | O8: =SUM('Monthly NII'!AO8:'Monthly NII'!AQ8) -> 1624.419
A9: Total loans (incl. HFS) | B9: 8723 | C9: 9057 | D9: 9696 | E9: 9934 | F9: 9920 | G9: 9993 | H9: 10547 | I9: 10434 | J9: 10157 | K9: 12449 | L9: =SUM('Monthly NII'!AF9:'Monthly NII'!AH9) -> 14610.784 | M9: =SUM('Monthly NII'!AI9:'Monthly NII'!AK9) -> 14542.182 | N9: =SUM('Monthly NII'!AL9:'Monthly NII'!AN9) -> 14473.508 | O9: =SUM('Monthly NII'!AO9:'Monthly NII'!AQ9) -> 14404.76
A10: Investment securities | B10: 615 | C10: 639 | D10: 627 | E10: 669 | F10: 687 | G10: 700 | H10: 733 | I10: 753 | J10: 770 | K10: 784 | L10: =SUM('Monthly NII'!AF10:'Monthly NII'!AH10) -> 695.2141 | M10: =SUM('Monthly NII'!AI10:'Monthly NII'!AK10) -> 663.60555 | N10: =SUM('Monthly NII'!AL10:'Monthly NII'!AN10) -> 631.997 | O10: =SUM('Monthly NII'!AO10:'Monthly NII'!AQ10) -> 600.38845
A11: Cash equivalents and other | B11: 416 | C11: 470 | D11: 550 | E11: 542 | F11: 570 | G11: 587 | H11: 580 | I11: 530 | J11: 491 | K11: 595 | L11: =SUM('Monthly NII'!AF11:'Monthly NII'!AH11) -> 687.27173 | M11: =SUM('Monthly NII'!AI11:'Monthly NII'!AK11) -> 676.06818 | N11: =SUM('Monthly NII'!AL11:'Monthly NII'!AN11) -> 664.85284 | O11: =SUM('Monthly NII'!AO11:'Monthly NII'!AQ11) -> 653.62569
A12: Total interest-earning assets | B12: 9754 | C12: 10166 | D12: 10873 | E12: 11145 | F12: 11177 | G12: 11280 | H12: 11860 | I12: 11717 | J12: 11418 | K12: 13828 | L12: =SUM('Monthly NII'!AF12:'Monthly NII'!AH12) -> 15993.27 | M12: =SUM('Monthly NII'!AI12:'Monthly NII'!AK12) -> 15881.856 | N12: =SUM('Monthly NII'!AL12:'Monthly NII'!AN12) -> 15770.357 | O12: =SUM('Monthly NII'!AO12:'Monthly NII'!AQ12) -> 15658.774
A14: INTEREST-BEARING LIABILITIES
A15: Interest-bearing deposits | B15: 1856 | C15: 2277 | D15: 2611 | E15: 2745 | F15: 2812 | G15: 2874 | H15: 2945 | I15: 2862 | J15: 2715 | K15: 3120 | L15: =SUM('Monthly NII'!AF15:'Monthly NII'!AH15) -> 3518.277 | M15: =SUM('Monthly NII'!AI15:'Monthly NII'!AK15) -> 3458.3912 | N15: =SUM('Monthly NII'!AL15:'Monthly NII'!AN15) -> 3398.4424 | O15: =SUM('Monthly NII'!AO15:'Monthly NII'!AQ15) -> 3338.4305
A16: Securitized debt obligations | B16: 211 | C16: 236 | D16: 249 | E16: 263 | F16: 261 | G16: 258 | H16: 234 | I16: 205 | J16: 176 | K16: 164 | L16: =SUM('Monthly NII'!AF16:'Monthly NII'!AH16) -> 184.14868 | M16: =SUM('Monthly NII'!AI16:'Monthly NII'!AK16) -> 176.17257 | N16: =SUM('Monthly NII'!AL16:'Monthly NII'!AN16) -> 168.39353 | O16: =SUM('Monthly NII'!AO16:'Monthly NII'!AQ16) -> 160.80745
A17: Senior and subordinated notes | B17: 489 | C17: 528 | D17: 579 | E17: 608 | F17: 606 | G17: 591 | H17: 596 | I17: 540 | J17: 505 | K17: 535 | L17: =SUM('Monthly NII'!AF17:'Monthly NII'!AH17) -> 598.51796 | M17: =SUM('Monthly NII'!AI17:'Monthly NII'!AK17) -> 589.73095 | N17: =SUM('Monthly NII'!AL17:'Monthly NII'!AN17) -> 580.94393 | O17: =SUM('Monthly NII'!AO17:'Monthly NII'!AQ17) -> 572.15692
A18: Other borrowings | B18: 12 | C18: 12 | D18: 11 | E18: 10 | F18: 10 | G18: 11 | H18: 9 | I18: 12 | J18: 9 | K18: 14 | L18: =SUM('Monthly NII'!AF18:'Monthly NII'!AH18) -> 5.02647 | M18: =SUM('Monthly NII'!AI18:'Monthly NII'!AK18) -> 4.782345 | N18: =SUM('Monthly NII'!AL18:'Monthly NII'!AN18) -> 4.53822 | O18: =SUM('Monthly NII'!AO18:'Monthly NII'!AQ18) -> 4.294095
A19: Total interest-bearing liabilities | B19: 2568 | C19: 3053 | D19: 3450 | E19: 3626 | F19: 3689 | G19: 3734 | H19: 3784 | I19: 3619 | J19: 3405 | K19: 3833 | L19: =SUM('Monthly NII'!AF19:'Monthly NII'!AH19) -> 4305.9701 | M19: =SUM('Monthly NII'!AI19:'Monthly NII'!AK19) -> 4229.0771 | N19: =SUM('Monthly NII'!AL19:'Monthly NII'!AN19) -> 4152.3181 | O19: =SUM('Monthly NII'!AO19:'Monthly NII'!AQ19) -> 4075.689
A21: NET INTEREST INCOME | B21: =B12-B19 -> 7186 | C21: =C12-C19 -> 7113 | D21: =D12-D19 -> 7423 | E21: =E12-E19 -> 7519 | F21: =F12-F19 -> 7488 | G21: =G12-G19 -> 7546 | H21: =H12-H19 -> 8076 | I21: =I12-I19 -> 8098 | ... K21: =K12-K19 -> 9995 | L21: =SUM('Monthly NII'!AF21:'Monthly NII'!AH21) -> 11687.3 | M21: =SUM('Monthly NII'!AI21:'Monthly NII'!AK21) -> 11652.779 | N21: =SUM('Monthly NII'!AL21:'Monthly NII'!AN21) -> 11618.039 | O21: =SUM('Monthly NII'!AO21:'Monthly NII'!AQ21) -> 11583.085
A23: CHECK: NII vs income statement (flows.csv)
A24: Income statement NII (XBRL) | B24: 7186 | C24: 7113 | D24: 7423 | E24: 7519 | F24: 7488 | G24: 7546 | H24: 8076 | I24: 8098 | J24: 8013 | K24: 9995
A25: Difference | B25: =IF(B24="","",B21-B24) -> 0 | C25: =IF(C24="","",C21-C24) -> 0 | D25: =IF(D24="","",D21-D24) -> 0 | E25: =IF(E24="","",E21-E24) -> 0 | F25: =IF(F24="","",F21-F24) -> 0 | G25: =IF(G24="","",G21-G24) -> 0 | H25: =IF(H24="","",H21-H24) -> 0 | I25: =IF(I24="","",I21-I24) -> 0 | ... K25: =IF(K24="","",K21-K24) -> 0
A27: Blue = as disclosed. Green = from the XBRL income statement (independent source). Black = formula. Difference should be zero: the MD&A average-balance table and the income statement must agree on NII.
J28: 6month NII | K28: =SUM(J21:K21) -> 18008 | O28: =SUM(N21:O21) -> 23201.124

Sheet Notes & Sources
A1: Balance / Rate / Net Interest Income — Capital One
A3: ON "GL ACCOUNTS"
A4: SEC filings do not expose a general ledger. These rows are the line items Capital One discloses in its average-balance table — the finest account-level granularity available externally. They are groupings, not GL account numbers.
A6: WHAT EACH TABLE HOLDS
A7: Balance — AVERAGE balance over the quarter, in $mm. Not period-end; it will not tie to the balance sheet.
A8: Rate — annualised yield (assets) and cost of funds (liabilities), stored as fractions and displayed as percentages.
A9: Net Interest Income — interest income on assets and interest expense on liabilities, with NII computed as the difference of the totals.
A11: SOURCE
A12: Capital One Financial Corp (CIK 0000927628), Forms 10-Q and 10-K, MD&A table 'Average Balances, Net Interest Income and Net Interest Margin'. These MD&A tables are NOT XBRL-tagged, so values are parsed from the rendered HTML.
A14: Q4 DERIVATION, AND WHY IT IS SOUND
A15: No 3-month Q4 average-balance table is published: the 10-K table is annual and the 10-Q tables are 3/6/9-month. Q4 columns are marked (D).
A16: Two identities were tested against the actual data, both passing 48 of 48 cases: interest is additive (6M = Q1 + Q2), and average balances weight by months (6M avg = (Q1 avg x3 + Q2 avg x3) / 6).
... A42: Macro inputs and calibration values are shown on Forecast Drivers.

Sheet Quarter-End Anchors
A1: Quarter-End Balance Anchors ($mm)
A2: Reported balance-sheet controls through Jun-25. Forecast quarter ends thereafter link to the monthly balance forecast; filing source controls are intentionally blank.
A4: Line item / source control | B4: 44926 | C4: 45016 | D4: 45107 | E4: 45199 | F4: 45291 | G4: 45382 | H4: 45473 | I4: 45565 | J4: 45657 | K4: 45747 | L4: 45838 | M4: 45930 | N4: 46022 | O4: 46112 | P4: 46203
A5: INTEREST-EARNING ASSETS
A6: Credit card | C6: =IF(ISNUMBER(C9),C9*Balance!B6/Balance!B9,"") | D6: =IF(ISNUMBER(D9),D9*Balance!C6/Balance!C9,"") | E6: =IF(ISNUMBER(E9),E9*Balance!D6/Balance!D9,"") | F6: =IF(ISNUMBER(F9),F9*Balance!E6/Balance!E9,"") -> 150877.97 | G6: =IF(ISNUMBER(G9),G9*Balance!F6/Balance!F9,"") -> 149854.52 | H6: =IF(ISNUMBER(H9),H9*Balance!G6/Balance!G9,"") -> 151994.79 | I6: =IF(ISNUMBER(I9),I9*Balance!H6/Balance!H9,"") -> 154899.08 | J6: =IF(ISNUMBER(J9),J9*Balance!I6/Balance!I9,"") -> 160051.49 | ... L6: =IF(ISNUMBER(L9),L9*Balance!K6/Balance!K9,"") -> 243351.39 | M6: ='Monthly EOP Balance'!AI6 -> 243475.77 | N6: ='Monthly EOP Balance'!AL6 -> 243600.15 | O6: ='Monthly EOP Balance'!AO6 -> 243724.53 | P6: ='Monthly EOP Balance'!AR6 -> 243848.91
A7: Consumer banking | C7: =IF(ISNUMBER(C9),C9*Balance!B7/Balance!B9,"") | D7: =IF(ISNUMBER(D9),D9*Balance!C7/Balance!C9,"") | E7: =IF(ISNUMBER(E9),E9*Balance!D7/Balance!D9,"") | F7: =IF(ISNUMBER(F9),F9*Balance!E7/Balance!E9,"") -> 77126.738 | G7: =IF(ISNUMBER(G9),G9*Balance!F7/Balance!F9,"") -> 74993.675 | H7: =IF(ISNUMBER(H9),H9*Balance!G7/Balance!G9,"") -> 75950.041 | I7: =IF(ISNUMBER(I9),I9*Balance!H7/Balance!H9,"") -> 76547.236 | J7: =IF(ISNUMBER(J9),J9*Balance!I7/Balance!I9,"") -> 78551.962 | ... L7: =IF(ISNUMBER(L9),L9*Balance!K7/Balance!K9,"") -> 92951.266 | M7: ='Monthly EOP Balance'!AI7 -> 92901.807 | N7: ='Monthly EOP Balance'!AL7 -> 92852.348 | O7: ='Monthly EOP Balance'!AO7 -> 92802.89 | P7: ='Monthly EOP Balance'!AR7 -> 92753.431
A8: Commercial banking | C8: =IF(ISNUMBER(C9),C9*Balance!B8/Balance!B9,"") | D8: =IF(ISNUMBER(D9),D9*Balance!C8/Balance!C9,"") | E8: =IF(ISNUMBER(E9),E9*Balance!D8/Balance!D9,"") | F8: =IF(ISNUMBER(F9),F9*Balance!E8/Balance!E9,"") -> 92467.294 | G8: =IF(ISNUMBER(G9),G9*Balance!F8/Balance!F9,"") -> 90305.803 | H8: =IF(ISNUMBER(H9),H9*Balance!G8/Balance!G9,"") -> 90241.174 | I8: =IF(ISNUMBER(I9),I9*Balance!H8/Balance!H9,"") -> 88796.682 | J8: =IF(ISNUMBER(J9),J9*Balance!I8/Balance!I9,"") -> 89171.546 | ... L8: =IF(ISNUMBER(L9),L9*Balance!K8/Balance!K9,"") -> 102994.34 | M8: ='Monthly EOP Balance'!AI8 -> 103046.98 | N8: ='Monthly EOP Balance'!AL8 -> 103099.63 | O8: ='Monthly EOP Balance'!AO8 -> 103152.27 | P8: ='Monthly EOP Balance'!AR8 -> 103204.91
A9: Total loans (incl. HFS) | B9: =IF(ISNUMBER(B24),B24,"") | C9: =IF(ISNUMBER(C24),C24,"") | D9: =IF(ISNUMBER(D24),D24,"") | E9: =IF(ISNUMBER(E24),E24,"") | F9: =IF(ISNUMBER(F24),F24,"") -> 320472 | G9: =IF(ISNUMBER(G24),G24,"") -> 315154 | H9: =IF(ISNUMBER(H24),H24,"") -> 318186 | I9: =IF(ISNUMBER(I24),I24,"") -> 320243 | ... L9: =IF(ISNUMBER(L24),L24,"") -> 439297 | M9: ='Monthly EOP Balance'!AI9 -> 439424.56 | N9: ='Monthly EOP Balance'!AL9 -> 439552.13 | O9: ='Monthly EOP Balance'!AO9 -> 439679.69 | P9: ='Monthly EOP Balance'!AR9 -> 439807.25
A10: Investment securities | B10: =IF(COUNT(B25:B26)=0,"",SUM(B25:B26)) | C10: =IF(COUNT(C25:C26)=0,"",SUM(C25:C26)) | D10: =IF(COUNT(D25:D26)=0,"",SUM(D25:D26)) | E10: =IF(COUNT(E25:E26)=0,"",SUM(E25:E26)) | F10: =IF(COUNT(F25:F26)=0,"",SUM(F25:F26)) -> 79117 | G10: =IF(COUNT(G25:G26)=0,"",SUM(G25:G26)) -> 78398 | H10: =IF(COUNT(H25:H26)=0,"",SUM(H25:H26)) -> 79250 | I10: =IF(COUNT(I25:I26)=0,"",SUM(I25:I26)) -> 83500 | ... L10: =IF(COUNT(L25:L26)=0,"",SUM(L25:L26)) -> 87196 | M10: ='Monthly EOP Balance'!AI10 -> 87196 | N10: ='Monthly EOP Balance'!AL10 -> 87196 | O10: ='Monthly EOP Balance'!AO10 -> 87196 | P10: ='Monthly EOP Balance'!AR10 -> 87196
A11: Cash equivalents and other | B11: =IF(ISNUMBER(B27),B27,"") -> 31256 | C11: =IF(ISNUMBER(C27),C27,"") -> 46973 | D11: =IF(ISNUMBER(D27),D27,"") -> 42048 | E11: =IF(ISNUMBER(E27),E27,"") -> 45304 | F11: =IF(ISNUMBER(F27),F27,"") -> 43755 | G11: =IF(ISNUMBER(G27),G27,"") -> 51502 | H11: =IF(ISNUMBER(H27),H27,"") -> 47829 | I11: =IF(ISNUMBER(I27),I27,"") -> 49719 | ... L11: =IF(ISNUMBER(L27),L27,"") -> 61578 | M11: ='Monthly EOP Balance'!AI11 -> 61609.473 | N11: ='Monthly EOP Balance'!AL11 -> 61640.947 | O11: ='Monthly EOP Balance'!AO11 -> 61672.42 | P11: ='Monthly EOP Balance'!AR11 -> 61703.893
A12: Total interest-earning assets | B12: =IF(COUNT(B9:B11)<3,"",SUM(B9:B11)) | C12: =IF(COUNT(C9:C11)<3,"",SUM(C9:C11)) | D12: =IF(COUNT(D9:D11)<3,"",SUM(D9:D11)) | E12: =IF(COUNT(E9:E11)<3,"",SUM(E9:E11)) | F12: =IF(COUNT(F9:F11)<3,"",SUM(F9:F11)) -> 443344 | G12: =IF(COUNT(G9:G11)<3,"",SUM(G9:G11)) -> 445054 | H12: =IF(COUNT(H9:H11)<3,"",SUM(H9:H11)) -> 445265 | I12: =IF(COUNT(I9:I11)<3,"",SUM(I9:I11)) -> 453462 | ... L12: =IF(COUNT(L9:L11)<3,"",SUM(L9:L11)) -> 588071 | M12: ='Monthly EOP Balance'!AI12 -> 588230.04 | N12: ='Monthly EOP Balance'!AL12 -> 588389.07 | O12: ='Monthly EOP Balance'!AO12 -> 588548.11 | P12: ='Monthly EOP Balance'!AR12 -> 588707.14
A14: INTEREST-BEARING LIABILITIES
A15: Interest-bearing deposits | B15: =IF(ISNUMBER(B28),B28,"") | C15: =IF(ISNUMBER(C28),C28,"") | D15: =IF(ISNUMBER(D28),D28,"") | E15: =IF(ISNUMBER(E28),E28,"") | F15: =IF(ISNUMBER(F28),F28,"") -> 320389 | G15: =IF(ISNUMBER(G28),G28,"") -> 323352 | H15: =IF(ISNUMBER(H28),H28,"") -> 324437 | I15: =IF(ISNUMBER(I28),I28,"") -> 327253 | ... L15: =IF(ISNUMBER(L28),L28,"") -> 440231 | M15: ='Monthly EOP Balance'!AI15 -> 440456.01 | N15: ='Monthly EOP Balance'!AL15 -> 440681.01 | O15: ='Monthly EOP Balance'!AO15 -> 440906.02 | P15: ='Monthly EOP Balance'!AR15 -> 441131.03
A16: Securitized debt obligations | C16: =IF(ISNUMBER(C29),C29*Balance!B16/SUM(Balance!B16:'Balance'!B17),"") | D16: =IF(ISNUMBER(D29),D29*Balance!C16/SUM(Balance!C16:'Balance'!C17),"") | E16: =IF(ISNUMBER(E29),E29*Balance!D16/SUM(Balance!D16:'Balance'!D17),"") | F16: =IF(ISNUMBER(F29),F29*Balance!E16/SUM(Balance!E16:'Balance'!E17),"") -> 17559.23 | G16: =IF(ISNUMBER(G29),G29*Balance!F16/SUM(Balance!F16:'Balance'!F17),"") -> 17745.478 | H16: =IF(ISNUMBER(H29),H29*Balance!G16/SUM(Balance!G16:'Balance'!G17),"") -> 17023.538 | I16: =IF(ISNUMBER(I29),I29*Balance!H16/SUM(Balance!H16:'Balance'!H17),"") -> 16144.54 | J16: =IF(ISNUMBER(J29),J29*Balance!I16/SUM(Balance!I16:'Balance'!I17),"") -> 14654.525 | ... L16: =IF(ISNUMBER(L29),L29*Balance!K16/SUM(Balance!K16:'Balance'!K17),"") -> 14749.967 | M16: ='Monthly EOP Balance'!AI16 -> 14529.822 | N16: ='Monthly EOP Balance'!AL16 -> 14312.962 | O16: ='Monthly EOP Balance'!AO16 -> 14099.34 | P16: ='Monthly EOP Balance'!AR16 -> 13888.905
A17: Senior and subordinated notes | C17: =IF(ISNUMBER(C29),C29*Balance!B17/SUM(Balance!B16:'Balance'!B17),"") | D17: =IF(ISNUMBER(D29),D29*Balance!C17/SUM(Balance!C16:'Balance'!C17),"") | E17: =IF(ISNUMBER(E29),E29*Balance!D17/SUM(Balance!D16:'Balance'!D17),"") | F17: =IF(ISNUMBER(F29),F29*Balance!E17/SUM(Balance!E16:'Balance'!E17),"") -> 31758.77 | G17: =IF(ISNUMBER(G29),G29*Balance!F17/SUM(Balance!F16:'Balance'!F17),"") -> 32047.522 | H17: =IF(ISNUMBER(H29),H29*Balance!G17/SUM(Balance!G16:'Balance'!G17),"") -> 30217.462 | I17: =IF(ISNUMBER(I29),I29*Balance!H17/SUM(Balance!H16:'Balance'!H17),"") -> 32671.46 | J17: =IF(ISNUMBER(J29),J29*Balance!I17/SUM(Balance!I16:'Balance'!I17),"") -> 30334.475 | ... L17: =IF(ISNUMBER(L29),L29*Balance!K17/SUM(Balance!K16:'Balance'!K17),"") -> 37174.033 | M17: ='Monthly EOP Balance'!AI17 -> 37174.033 | N17: ='Monthly EOP Balance'!AL17 -> 37174.033 | O17: ='Monthly EOP Balance'!AO17 -> 37174.033 | P17: ='Monthly EOP Balance'!AR17 -> 37174.033
A18: Other borrowings | B18: =IF(COUNT(B30:B31)<2,"",SUM(B30:B31)) | C18: =IF(COUNT(C30:C31)<2,"",SUM(C30:C31)) | D18: =IF(COUNT(D30:D31)<2,"",SUM(D30:D31)) | E18: =IF(COUNT(E30:E31)<2,"",SUM(E30:E31)) | F18: =IF(COUNT(F30:F31)<2,"",SUM(F30:F31)) -> 565 | G18: =IF(COUNT(G30:G31)<2,"",SUM(G30:G31)) -> 592 | H18: =IF(COUNT(H30:H31)<2,"",SUM(H30:H31)) -> 740 | I18: =IF(COUNT(I30:I31)<2,"",SUM(I30:I31)) -> 544 | ... L18: =IF(COUNT(L30:L31)<2,"",SUM(L30:L31)) -> 1302 | M18: ='Monthly EOP Balance'!AI18 -> 1302 | N18: ='Monthly EOP Balance'!AL18 -> 1302 | O18: ='Monthly EOP Balance'!AO18 -> 1302 | P18: ='Monthly EOP Balance'!AR18 -> 1302
A19: Total interest-bearing liabilities | B19: =IF(COUNT(B15:B18)<4,"",SUM(B15:B18)) | C19: =IF(COUNT(C15:C18)<4,"",SUM(C15:C18)) | D19: =IF(COUNT(D15:D18)<4,"",SUM(D15:D18)) | E19: =IF(COUNT(E15:E18)<4,"",SUM(E15:E18)) | F19: =IF(COUNT(F15:F18)<4,"",SUM(F15:F18)) -> 370272 | G19: =IF(COUNT(G15:G18)<4,"",SUM(G15:G18)) -> 373737 | H19: =IF(COUNT(H15:H18)<4,"",SUM(H15:H18)) -> 372418 | I19: =IF(COUNT(I15:I18)<4,"",SUM(I15:I18)) -> 376613 | ... L19: =IF(COUNT(L15:L18)<4,"",SUM(L15:L18)) -> 493457 | M19: ='Monthly EOP Balance'!AI19 -> 493461.86 | N19: ='Monthly EOP Balance'!AL19 -> 493470.01 | O19: ='Monthly EOP Balance'!AO19 -> 493481.39 | P19: ='Monthly EOP Balance'!AR19 -> 493495.97
A21: Net earning assets (assets − liabilities) | B21: =IF(COUNT(B12,B19)<2,"",B12-B19) | C21: =IF(COUNT(C12,C19)<2,"",C12-C19) | D21: =IF(COUNT(D12,D19)<2,"",D12-D19) | E21: =IF(COUNT(E12,E19)<2,"",E12-E19) | F21: =IF(COUNT(F12,F19)<2,"",F12-F19) -> 73072 | G21: =IF(COUNT(G12,G19)<2,"",G12-G19) -> 71317 | H21: =IF(COUNT(H12,H19)<2,"",H12-H19) -> 72847 | I21: =IF(COUNT(I12,I19)<2,"",I12-I19) -> 76849 | ... L21: =IF(COUNT(L12,L19)<2,"",L12-L19) -> 94614 | M21: ='Monthly EOP Balance'!AI21 -> 94768.174 | N21: ='Monthly EOP Balance'!AL21 -> 94919.062 | O21: ='Monthly EOP Balance'!AO21 -> 95066.713 | P21: ='Monthly EOP Balance'!AR21 -> 95211.177
A23: SOURCE CONTROLS
A24: Loans HFI, gross | F24: 320472 | G24: 315154 | H24: 318186 | I24: 320243 | J24: 327775 | K24: 323598 | L24: 439297
A25: Securities AFS | F25: 79117 | G25: 78398 | H25: 79250 | I25: 83500 | J25: 83013 | K25: 84362 | L25: 87196
A26: Securities HTM
A27: Cash and cash equivalents | B27: 31256 | C27: 46973 | D27: 42048 | E27: 45304 | F27: 43755 | G27: 51502 | H27: 47829 | I27: 49719 | J27: 43671 | K27: 48965 | L27: 61578
A28: Interest-bearing deposits | F28: 320389 | G28: 323352 | H28: 324437 | I28: 327253 | J28: 336585 | K28: 340964 | L28: 440231
A29: Long-term debt | F29: 49318 | G29: 49793 | H29: 47241 | I29: 48816 | J29: 44989 | K29: 41200 | L29: 51924
A30: Short-term borrowings | F30: 538 | G30: 568 | H30: 715 | I30: 520 | J30: 562 | K30: 573 | L30: 742
A31: Other borrowings | F31: 27 | G31: 24 | H31: 25 | I31: 24 | J31: 29 | K31: 25 | L31: 560

Sheet Monthly EOP Balance
A1: Capital One - Imputed Monthly End-of-Period Balance by line item ($mm)
A2: Reported and controlled month ends through Jun-25. Jul-25 through Jun-26 is a macro-driven balance forecast.
A4: Line item (as disclosed) | B4: 44926 | C4: 44957 | D4: 44985 | E4: 45016 | F4: 45046 | G4: 45077 | H4: 45107 | I4: 45138 | J4: 45169 | K4: 45199 | L4: 45230 | M4: 45260 | N4: 45291 | O4: 45322 | P4: 45351 | Q4: 45382 | R4: 45412 | S4: 45443 | T4: 45473 | U4: 45504 | V4: 45535 | W4: 45565 | X4: 45596 | Y4: 45626 | Z4: 45657 | AA4: 45688 | AB4: 45716 | AC4: 45747 | AD4: 45777 | AE4: 45808 | AF4: 45838 | AG4: 45869 | AH4: 45900 | AI4: 45930 | AJ4: 45961 | AK4: 45991 | AL4: 46022 | AM4: 46053 | AN4: 46081 | AO4: 46112 | AP4: 46142 | AQ4: 46173 | AR4: 46203
A5: INTEREST-EARNING ASSETS
A6: Credit card | B6: =IF(ISNUMBER('Quarter-End Anchors'!B6),'Quarter-End Anchors'!B6,Balance!B6) -> 134669 | C6: =B6+(E6-B6)/3+(2*Balance!B6-B6-E6) -> 134669 | D6: =B6+2*(E6-B6)/3+(2*Balance!B6-B6-E6) -> 134669 | E6: =IF(ISNUMBER('Quarter-End Anchors'!C6),'Quarter-End Anchors'!C6,2*Balance!B6-B6) -> 134669 | F6: =E6+(H6-E6)/3+(2*Balance!C6-E6-H6) -> 137397.67 | G6: =E6+2*(H6-E6)/3+(2*Balance!C6-E6-H6) -> 140126.33 | H6: =IF(ISNUMBER('Quarter-End Anchors'!D6),'Quarter-End Anchors'!D6,2*Balance!C6-E6) -> 142855 | I6: =H6+(K6-H6)/3+(2*Balance!D6-H6-K6) -> 143653.67 | J6: =H6+2*(K6-H6)/3+(2*Balance!D6-H6-K6) -> 144452.33 | K6: =IF(ISNUMBER('Quarter-End Anchors'!E6),'Quarter-End Anchors'!E6,2*Balance!D6-H6) -> 145251 | L6: =K6+(N6-K6)/3+(2*Balance!E6-K6-N6) -> 149221.69 | M6: =K6+2*(N6-K6)/3+(2*Balance!E6-K6-N6) -> 151097.34 | N6: =IF(ISNUMBER('Quarter-End Anchors'!F6),'Quarter-End Anchors'!F6,2*Balance!E6-K6) -> 150877.97 | O6: =N6+(Q6-N6)/3+(2*Balance!F6-N6-Q6) -> 149902.33 | P6: =N6+2*(Q6-N6)/3+(2*Balance!F6-N6-Q6) -> 149561.18 | Q6: =IF(ISNUMBER('Quarter-End Anchors'!G6),'Quarter-End Anchors'!G6,2*Balance!F6-N6) -> 149854.52 | R6: =Q6+(T6-Q6)/3+(2*Balance!G6-Q6-T6) -> 150450.64 | S6: =Q6+2*(T6-Q6)/3+(2*Balance!G6-Q6-T6) -> 151164.06 | T6: =IF(ISNUMBER('Quarter-End Anchors'!H6),'Quarter-End Anchors'!H6,2*Balance!G6-Q6) -> 151994.79 | U6: =T6+(W6-T6)/3+(2*Balance!H6-T6-W6) -> 154389.02 | V6: =T6+2*(W6-T6)/3+(2*Balance!H6-T6-W6) -> 155357.12 | W6: =IF(ISNUMBER('Quarter-End Anchors'!I6),'Quarter-End Anchors'!I6,2*Balance!H6-T6) -> 154899.08 | X6: =W6+(Z6-W6)/3+(2*Balance!I6-W6-Z6) -> 156385.98 | Y6: =W6+2*(Z6-W6)/3+(2*Balance!I6-W6-Z6) -> 158103.45 | Z6: =IF(ISNUMBER('Quarter-End Anchors'!J6),'Quarter-End Anchors'!J6,2*Balance!I6-W6) -> 160051.49 | AA6: =Z6+(AC6-Z6)/3+(2*Balance!J6-Z6-AC6) -> 154926.66 | AB6: =Z6+2*(AC6-Z6)/3+(2*Balance!J6-Z6-AC6) -> 153845.58 | AC6: =IF(ISNUMBER('Quarter-End Anchors'!K6),'Quarter-End Anchors'!K6,2*Balance!J6-Z6) -> 156808.26 | AD6: =AC6+(AF6-AC6)/3+(2*Balance!K6-AC6-AF6) -> 204882.32 | AE6: =AC6+2*(AF6-AC6)/3+(2*Balance!K6-AC6-AF6) -> 233730.03 | AF6: =IF(ISNUMBER('Quarter-End Anchors'!L6),'Quarter-End Anchors'!L6,2*Balance!K6-AC6) -> 243351.39 | AG6: =AF6*('Forecast Drivers'!C12/'Forecast Drivers'!B12)*((1-'Forecast Drivers'!C11/100)/(1-'Forecast Drivers'!B11/100)) -> 243392.85 | AH6: =AG6*('Forecast Drivers'!D12/'Forecast Drivers'!C12)*((1-'Forecast Drivers'!D11/100)/(1-'Forecast Drivers'!C11/100)) -> 243434.31 | AI6: =AH6*('Forecast Drivers'!E12/'Forecast Drivers'!D12)*((1-'Forecast Drivers'!E11/100)/(1-'Forecast Drivers'!D11/100)) -> 243475.77 | AJ6: =AI6*('Forecast Drivers'!F12/'Forecast Drivers'!E12)*((1-'Forecast Drivers'!F11/100)/(1-'Forecast Drivers'!E11/100)) -> 243517.23 | AK6: =AJ6*('Forecast Drivers'!G12/'Forecast Drivers'!F12)*((1-'Forecast Drivers'!G11/100)/(1-'Forecast Drivers'!F11/100)) -> 243558.69 | AL6: =AK6*('Forecast Drivers'!H12/'Forecast Drivers'!G12)*((1-'Forecast Drivers'!H11/100)/(1-'Forecast Drivers'!G11/100)) -> 243600.15 | AM6: =AL6*('Forecast Drivers'!I12/'Forecast Drivers'!H12)*((1-'Forecast Drivers'!I11/100)/(1-'Forecast Drivers'!H11/100)) -> 243641.61 | AN6: =AM6*('Forecast Drivers'!J12/'Forecast Drivers'!I12)*((1-'Forecast Drivers'!J11/100)/(1-'Forecast Drivers'!I11/100)) -> 243683.07 | ... AR6: =AQ6*('Forecast Drivers'!N12/'Forecast Drivers'!M12)*((1-'Forecast Drivers'!N11/100)/(1-'Forecast Drivers'!M11/100)) -> 243848.91
A7: Consumer banking | B7: =IF(ISNUMBER('Quarter-End Anchors'!B7),'Quarter-End Anchors'!B7,Balance!B7) -> 79000 | C7: =B7+(E7-B7)/3+(2*Balance!B7-B7-E7) -> 79000 | D7: =B7+2*(E7-B7)/3+(2*Balance!B7-B7-E7) -> 79000 | E7: =IF(ISNUMBER('Quarter-End Anchors'!C7),'Quarter-End Anchors'!C7,2*Balance!B7-B7) -> 79000 | F7: =E7+(H7-E7)/3+(2*Balance!C7-E7-H7) -> 78132.667 | G7: =E7+2*(H7-E7)/3+(2*Balance!C7-E7-H7) -> 77265.333 | H7: =IF(ISNUMBER('Quarter-End Anchors'!D7),'Quarter-End Anchors'!D7,2*Balance!C7-E7) -> 76398 | I7: =H7+(K7-H7)/3+(2*Balance!D7-H7-K7) -> 76902 | J7: =H7+2*(K7-H7)/3+(2*Balance!D7-H7-K7) -> 77406 | K7: =IF(ISNUMBER('Quarter-End Anchors'!E7),'Quarter-End Anchors'!E7,2*Balance!D7-H7) -> 77910 | L7: =K7+(N7-K7)/3+(2*Balance!E7-K7-N7) -> 75060.174 | M7: =K7+2*(N7-K7)/3+(2*Balance!E7-K7-N7) -> 74799.087 | N7: =IF(ISNUMBER('Quarter-End Anchors'!F7),'Quarter-End Anchors'!F7,2*Balance!E7-K7) -> 77126.738 | O7: =N7+(Q7-N7)/3+(2*Balance!F7-N7-Q7) -> 74477.304 | P7: =N7+2*(Q7-N7)/3+(2*Balance!F7-N7-Q7) -> 73766.283 | Q7: =IF(ISNUMBER('Quarter-End Anchors'!G7),'Quarter-End Anchors'!G7,2*Balance!F7-N7) -> 74993.675 | R7: =Q7+(T7-Q7)/3+(2*Balance!G7-Q7-T7) -> 75140.748 | S7: =Q7+2*(T7-Q7)/3+(2*Balance!G7-Q7-T7) -> 75459.536 | T7: =IF(ISNUMBER('Quarter-End Anchors'!H7),'Quarter-End Anchors'!H7,2*Balance!G7-Q7) -> 75950.041 | U7: =T7+(W7-T7)/3+(2*Balance!H7-T7-W7) -> 76015.829 | V7: =T7+2*(W7-T7)/3+(2*Balance!H7-T7-W7) -> 76214.894 | W7: =IF(ISNUMBER('Quarter-End Anchors'!I7),'Quarter-End Anchors'!I7,2*Balance!H7-T7) -> 76547.236 | X7: =W7+(Z7-W7)/3+(2*Balance!I7-W7-Z7) -> 76578.28 | Y7: =W7+2*(Z7-W7)/3+(2*Balance!I7-W7-Z7) -> 77246.522 | Z7: =IF(ISNUMBER('Quarter-End Anchors'!J7),'Quarter-End Anchors'!J7,2*Balance!I7-W7) -> 78551.962 | AA7: =Z7+(AC7-Z7)/3+(2*Balance!J7-Z7-AC7) -> 78322.121 | AB7: =Z7+2*(AC7-Z7)/3+(2*Balance!J7-Z7-AC7) -> 78365.08 | AC7: =IF(ISNUMBER('Quarter-End Anchors'!K7),'Quarter-End Anchors'!K7,2*Balance!J7-Z7) -> 78680.837 | AD7: =AC7+(AF7-AC7)/3+(2*Balance!K7-AC7-AF7) -> 71995.544 | AE7: =AC7+2*(AF7-AC7)/3+(2*Balance!K7-AC7-AF7) -> 76752.354 | AF7: =IF(ISNUMBER('Quarter-End Anchors'!L7),'Quarter-End Anchors'!L7,2*Balance!K7-AC7) -> 92951.266 | AG7: =AF7*('Forecast Drivers'!C9/'Forecast Drivers'!B9) -> 92934.779 | AH7: =AG7*('Forecast Drivers'!D9/'Forecast Drivers'!C9) -> 92918.293 | AI7: =AH7*('Forecast Drivers'!E9/'Forecast Drivers'!D9) -> 92901.807 | AJ7: =AI7*('Forecast Drivers'!F9/'Forecast Drivers'!E9) -> 92885.321 | AK7: =AJ7*('Forecast Drivers'!G9/'Forecast Drivers'!F9) -> 92868.834 | AL7: =AK7*('Forecast Drivers'!H9/'Forecast Drivers'!G9) -> 92852.348 | AM7: =AL7*('Forecast Drivers'!I9/'Forecast Drivers'!H9) -> 92835.862 | AN7: =AM7*('Forecast Drivers'!J9/'Forecast Drivers'!I9) -> 92819.376 | ... AR7: =AQ7*('Forecast Drivers'!N9/'Forecast Drivers'!M9) -> 92753.431
A8: Commercial banking | B8: =IF(ISNUMBER('Quarter-End Anchors'!B8),'Quarter-End Anchors'!B8,Balance!B8) -> 94446 | C8: =B8+(E8-B8)/3+(2*Balance!B8-B8-E8) -> 94446 | D8: =B8+2*(E8-B8)/3+(2*Balance!B8-B8-E8) -> 94446 | E8: =IF(ISNUMBER('Quarter-End Anchors'!C8),'Quarter-End Anchors'!C8,2*Balance!B8-B8) -> 94446 | F8: =E8+(H8-E8)/3+(2*Balance!C8-E8-H8) -> 94064.667 | G8: =E8+2*(H8-E8)/3+(2*Balance!C8-E8-H8) -> 93683.333 | H8: =IF(ISNUMBER('Quarter-End Anchors'!D8),'Quarter-End Anchors'!D8,2*Balance!C8-E8) -> 93302 | I8: =H8+(K8-H8)/3+(2*Balance!D8-H8-K8) -> 92603.333 | J8: =H8+2*(K8-H8)/3+(2*Balance!D8-H8-K8) -> 91904.667 | K8: =IF(ISNUMBER('Quarter-End Anchors'!E8),'Quarter-End Anchors'!E8,2*Balance!D8-H8) -> 91206 | L8: =K8+(N8-K8)/3+(2*Balance!E8-K8-N8) -> 90723.138 | M8: =K8+2*(N8-K8)/3+(2*Balance!E8-K8-N8) -> 91143.569 | N8: =IF(ISNUMBER('Quarter-End Anchors'!F8),'Quarter-End Anchors'!F8,2*Balance!E8-K8) -> 92467.294 | O8: =N8+(Q8-N8)/3+(2*Balance!F8-N8-Q8) -> 89819.7 | P8: =N8+2*(Q8-N8)/3+(2*Balance!F8-N8-Q8) -> 89099.203 | Q8: =IF(ISNUMBER('Quarter-End Anchors'!G8),'Quarter-End Anchors'!G8,2*Balance!F8-N8) -> 90305.803 | R8: =Q8+(T8-Q8)/3+(2*Balance!G8-Q8-T8) -> 88879.283 | S8: =Q8+2*(T8-Q8)/3+(2*Balance!G8-Q8-T8) -> 88857.74 | T8: =IF(ISNUMBER('Quarter-End Anchors'!H8),'Quarter-End Anchors'!H8,2*Balance!G8-Q8) -> 90241.174 | U8: =T8+(W8-T8)/3+(2*Balance!H8-T8-W8) -> 87467.82 | V8: =T8+2*(W8-T8)/3+(2*Balance!H8-T8-W8) -> 86986.323 | W8: =IF(ISNUMBER('Quarter-End Anchors'!I8),'Quarter-End Anchors'!I8,2*Balance!H8-T8) -> 88796.682 | X8: =W8+(Z8-W8)/3+(2*Balance!I8-W8-Z8) -> 86297.409 | Y8: =W8+2*(Z8-W8)/3+(2*Balance!I8-W8-Z8) -> 86422.363 | Z8: =IF(ISNUMBER('Quarter-End Anchors'!J8),'Quarter-End Anchors'!J8,2*Balance!I8-W8) -> 89171.546 | AA8: =Z8+(AC8-Z8)/3+(2*Balance!J8-Z8-AC8) -> 87304.883 | AB8: =Z8+2*(AC8-Z8)/3+(2*Balance!J8-Z8-AC8) -> 86950.669 | AC8: =IF(ISNUMBER('Quarter-End Anchors'!K8),'Quarter-End Anchors'!K8,2*Balance!J8-Z8) -> 88108.902 | AD8: =AC8+(AF8-AC8)/3+(2*Balance!K8-AC8-AF8) -> 79465.471 | AE8: =AC8+2*(AF8-AC8)/3+(2*Balance!K8-AC8-AF8) -> 84427.284 | AF8: =IF(ISNUMBER('Quarter-End Anchors'!L8),'Quarter-End Anchors'!L8,2*Balance!K8-AC8) -> 102994.34 | AG8: =AF8*('Forecast Drivers'!C12/'Forecast Drivers'!B12) -> 103011.89 | AH8: =AG8*('Forecast Drivers'!D12/'Forecast Drivers'!C12) -> 103029.44 | AI8: =AH8*('Forecast Drivers'!E12/'Forecast Drivers'!D12) -> 103046.98 | AJ8: =AI8*('Forecast Drivers'!F12/'Forecast Drivers'!E12) -> 103064.53 | AK8: =AJ8*('Forecast Drivers'!G12/'Forecast Drivers'!F12) -> 103082.08 | AL8: =AK8*('Forecast Drivers'!H12/'Forecast Drivers'!G12) -> 103099.63 | AM8: =AL8*('Forecast Drivers'!I12/'Forecast Drivers'!H12) -> 103117.17 | AN8: =AM8*('Forecast Drivers'!J12/'Forecast Drivers'!I12) -> 103134.72 | ... AR8: =AQ8*('Forecast Drivers'!N12/'Forecast Drivers'!M12) -> 103204.91
A9: Total loans (incl. HFS) | B9: =SUM(B6:B8) -> 308115 | C9: =SUM(C6:C8) -> 308115 | D9: =SUM(D6:D8) -> 308115 | E9: =SUM(E6:E8) -> 308115 | F9: =SUM(F6:F8) -> 309595 | G9: =SUM(G6:G8) -> 311075 | H9: =SUM(H6:H8) -> 312555 | I9: =SUM(I6:I8) -> 313159 | ... AR9: =SUM(AR6:AR8) -> 439807.25
A10: Investment securities | B10: =IF(ISNUMBER('Quarter-End Anchors'!B10),'Quarter-End Anchors'!B10,Balance!B10) -> 89960 | C10: =B10+(E10-B10)/3+(2*Balance!B10-B10-E10) -> 89960 | D10: =B10+2*(E10-B10)/3+(2*Balance!B10-B10-E10) -> 89960 | E10: =IF(ISNUMBER('Quarter-End Anchors'!C10),'Quarter-End Anchors'!C10,2*Balance!B10-B10) -> 89960 | F10: =E10+(H10-E10)/3+(2*Balance!C10-E10-H10) -> 89982.667 | G10: =E10+2*(H10-E10)/3+(2*Balance!C10-E10-H10) -> 90005.333 | H10: =IF(ISNUMBER('Quarter-End Anchors'!D10),'Quarter-End Anchors'!D10,2*Balance!C10-E10) -> 90028 | I10: =H10+(K10-H10)/3+(2*Balance!D10-H10-K10) -> 88572.667 | J10: =H10+2*(K10-H10)/3+(2*Balance!D10-H10-K10) -> 87117.333 | K10: =IF(ISNUMBER('Quarter-End Anchors'!E10),'Quarter-End Anchors'!E10,2*Balance!D10-H10) -> 85662 | L10: =K10+(N10-K10)/3+(2*Balance!E10-K10-N10) -> 95987.333 | M10: =K10+2*(N10-K10)/3+(2*Balance!E10-K10-N10) -> 93805.667 | N10: =IF(ISNUMBER('Quarter-End Anchors'!F10),'Quarter-End Anchors'!F10,2*Balance!E10-K10) -> 79117 | O10: =N10+(Q10-N10)/3+(2*Balance!F10-N10-Q10) -> 98524.333 | P10: =N10+2*(Q10-N10)/3+(2*Balance!F10-N10-Q10) -> 98284.667 | Q10: =IF(ISNUMBER('Quarter-End Anchors'!G10),'Quarter-End Anchors'!G10,2*Balance!F10-N10) -> 78398 | R10: =Q10+(T10-Q10)/3+(2*Balance!G10-Q10-T10) -> 100036 | S10: =Q10+2*(T10-Q10)/3+(2*Balance!G10-Q10-T10) -> 100320 | T10: =IF(ISNUMBER('Quarter-End Anchors'!H10),'Quarter-End Anchors'!H10,2*Balance!G10-Q10) -> 79250 | U10: =T10+(W10-T10)/3+(2*Balance!H10-T10-W10) -> 99204.667 | V10: =T10+2*(W10-T10)/3+(2*Balance!H10-T10-W10) -> 100621.33 | W10: =IF(ISNUMBER('Quarter-End Anchors'!I10),'Quarter-End Anchors'!I10,2*Balance!H10-T10) -> 83500 | X10: =W10+(Z10-W10)/3+(2*Balance!I10-W10-Z10) -> 101344.67 | Y10: =W10+2*(Z10-W10)/3+(2*Balance!I10-W10-Z10) -> 101182.33 | Z10: =IF(ISNUMBER('Quarter-End Anchors'!J10),'Quarter-End Anchors'!J10,2*Balance!I10-W10) -> 83013 | AA10: =Z10+(AC10-Z10)/3+(2*Balance!J10-Z10-AC10) -> 101405.67 | AB10: =Z10+2*(AC10-Z10)/3+(2*Balance!J10-Z10-AC10) -> 101855.33 | AC10: =IF(ISNUMBER('Quarter-End Anchors'!K10),'Quarter-End Anchors'!K10,2*Balance!J10-Z10) -> 84362 | AD10: =AC10+(AF10-AC10)/3+(2*Balance!K10-AC10-AF10) -> 99796.667 | AE10: =AC10+2*(AF10-AC10)/3+(2*Balance!K10-AC10-AF10) -> 100741.33 | AF10: =IF(ISNUMBER('Quarter-End Anchors'!L10),'Quarter-End Anchors'!L10,2*Balance!K10-AC10) -> 87196 | AG10: =AF10 -> 87196 | AH10: =AG10 -> 87196 | AI10: =AH10 -> 87196 | AJ10: =AI10 -> 87196 | AK10: =AJ10 -> 87196 | AL10: =AK10 -> 87196 | AM10: =AL10 -> 87196 | AN10: =AM10 -> 87196 | ... AR10: =AQ10 -> 87196
A11: Cash equivalents and other | B11: =IF(ISNUMBER('Quarter-End Anchors'!B11),'Quarter-End Anchors'!B11,Balance!B11) -> 31256 | C11: =B11+(E11-B11)/3+(2*Balance!B11-B11-E11) -> 32514 | D11: =B11+2*(E11-B11)/3+(2*Balance!B11-B11-E11) -> 37753 | E11: =IF(ISNUMBER('Quarter-End Anchors'!C11),'Quarter-End Anchors'!C11,2*Balance!B11-B11) -> 46973 | F11: =E11+(H11-E11)/3+(2*Balance!C11-E11-H11) -> 33930.333 | G11: =E11+2*(H11-E11)/3+(2*Balance!C11-E11-H11) -> 32288.667 | H11: =IF(ISNUMBER('Quarter-End Anchors'!D11),'Quarter-End Anchors'!D11,2*Balance!C11-E11) -> 42048 | I11: =H11+(K11-H11)/3+(2*Balance!D11-H11-K11) -> 40233.333 | J11: =H11+2*(K11-H11)/3+(2*Balance!D11-H11-K11) -> 41318.667 | K11: =IF(ISNUMBER('Quarter-End Anchors'!E11),'Quarter-End Anchors'!E11,2*Balance!D11-H11) -> 45304 | L11: =K11+(N11-K11)/3+(2*Balance!E11-K11-N11) -> 38978.667 | M11: =K11+2*(N11-K11)/3+(2*Balance!E11-K11-N11) -> 38462.333 | N11: =IF(ISNUMBER('Quarter-End Anchors'!F11),'Quarter-End Anchors'!F11,2*Balance!E11-K11) -> 43755 | O11: =N11+(Q11-N11)/3+(2*Balance!F11-N11-Q11) -> 38398.333 | P11: =N11+2*(Q11-N11)/3+(2*Balance!F11-N11-Q11) -> 40980.667 | Q11: =IF(ISNUMBER('Quarter-End Anchors'!G11),'Quarter-End Anchors'!G11,2*Balance!F11-N11) -> 51502 | R11: =Q11+(T11-Q11)/3+(2*Balance!G11-Q11-T11) -> 42114.667 | S11: =Q11+2*(T11-Q11)/3+(2*Balance!G11-Q11-T11) -> 40890.333 | T11: =IF(ISNUMBER('Quarter-End Anchors'!H11),'Quarter-End Anchors'!H11,2*Balance!G11-Q11) -> 47829 | U11: =T11+(W11-T11)/3+(2*Balance!H11-T11-W11) -> 41161 | V11: =T11+2*(W11-T11)/3+(2*Balance!H11-T11-W11) -> 41791 | W11: =IF(ISNUMBER('Quarter-End Anchors'!I11),'Quarter-End Anchors'!I11,2*Balance!H11-T11) -> 49719 | X11: =W11+(Z11-W11)/3+(2*Balance!I11-W11-Z11) -> 46647 | Y11: =W11+2*(Z11-W11)/3+(2*Balance!I11-W11-Z11) -> 44631 | Z11: =IF(ISNUMBER('Quarter-End Anchors'!J11),'Quarter-End Anchors'!J11,2*Balance!I11-W11) -> 43671 | AA11: =Z11+(AC11-Z11)/3+(2*Balance!J11-Z11-AC11) -> 47479.667 | AB11: =Z11+2*(AC11-Z11)/3+(2*Balance!J11-Z11-AC11) -> 49244.333 | AC11: =IF(ISNUMBER('Quarter-End Anchors'!K11),'Quarter-End Anchors'!K11,2*Balance!J11-Z11) -> 48965 | AD11: =AC11+(AF11-AC11)/3+(2*Balance!K11-AC11-AF11) -> 49362.333 | AE11: =AC11+2*(AF11-AC11)/3+(2*Balance!K11-AC11-AF11) -> 53566.667 | AF11: =IF(ISNUMBER('Quarter-End Anchors'!L11),'Quarter-End Anchors'!L11,2*Balance!K11-AC11) -> 61578 | AG11: =AG15*'Forecast Drivers'!$B$18 -> 61588.491 | AH11: =AH15*'Forecast Drivers'!$B$18 -> 61598.982 | AI11: =AI15*'Forecast Drivers'!$B$18 -> 61609.473 | AJ11: =AJ15*'Forecast Drivers'!$B$18 -> 61619.964 | AK11: =AK15*'Forecast Drivers'!$B$18 -> 61630.455 | AL11: =AL15*'Forecast Drivers'!$B$18 -> 61640.947 | AM11: =AM15*'Forecast Drivers'!$B$18 -> 61651.438 | AN11: =AN15*'Forecast Drivers'!$B$18 -> 61661.929 | ... AR11: =AR15*'Forecast Drivers'!$B$18 -> 61703.893
A12: Total interest-earning assets | B12: =SUM(B9:B11) -> 429331 | C12: =SUM(C9:C11) -> 430589 | D12: =SUM(D9:D11) -> 435828 | E12: =SUM(E9:E11) -> 445048 | F12: =SUM(F9:F11) -> 433508 | G12: =SUM(G9:G11) -> 433369 | H12: =SUM(H9:H11) -> 444631 | I12: =SUM(I9:I11) -> 441965 | ... AR12: =SUM(AR9:AR11) -> 588707.14
A14: INTEREST-BEARING LIABILITIES
A15: Interest-bearing deposits | B15: =IF(ISNUMBER('Quarter-End Anchors'!B15),'Quarter-End Anchors'!B15,Balance!B15) -> 308788 | C15: =B15+(E15-B15)/3+(2*Balance!B15-B15-E15) -> 308788 | D15: =B15+2*(E15-B15)/3+(2*Balance!B15-B15-E15) -> 308788 | E15: =IF(ISNUMBER('Quarter-End Anchors'!C15),'Quarter-End Anchors'!C15,2*Balance!B15-B15) -> 308788 | F15: =E15+(H15-E15)/3+(2*Balance!C15-E15-H15) -> 311734 | G15: =E15+2*(H15-E15)/3+(2*Balance!C15-E15-H15) -> 314680 | H15: =IF(ISNUMBER('Quarter-End Anchors'!D15),'Quarter-End Anchors'!D15,2*Balance!C15-E15) -> 317626 | I15: =H15+(K15-H15)/3+(2*Balance!D15-H15-K15) -> 316563.33 | J15: =H15+2*(K15-H15)/3+(2*Balance!D15-H15-K15) -> 315500.67 | K15: =IF(ISNUMBER('Quarter-End Anchors'!E15),'Quarter-End Anchors'!E15,2*Balance!D15-H15) -> 314438 | L15: =K15+(N15-K15)/3+(2*Balance!E15-K15-N15) -> 315278.67 | M15: =K15+2*(N15-K15)/3+(2*Balance!E15-K15-N15) -> 317262.33 | N15: =IF(ISNUMBER('Quarter-End Anchors'!F15),'Quarter-End Anchors'!F15,2*Balance!E15-K15) -> 320389 | O15: =N15+(Q15-N15)/3+(2*Balance!F15-N15-Q15) -> 314535.67 | P15: =N15+2*(Q15-N15)/3+(2*Balance!F15-N15-Q15) -> 315523.33 | Q15: =IF(ISNUMBER('Quarter-End Anchors'!G15),'Quarter-End Anchors'!G15,2*Balance!F15-N15) -> 323352 | R15: =Q15+(T15-Q15)/3+(2*Balance!G15-Q15-T15) -> 321086.67 | S15: =Q15+2*(T15-Q15)/3+(2*Balance!G15-Q15-T15) -> 321448.33 | T15: =IF(ISNUMBER('Quarter-End Anchors'!H15),'Quarter-End Anchors'!H15,2*Balance!G15-Q15) -> 324437 | U15: =T15+(W15-T15)/3+(2*Balance!H15-T15-W15) -> 322703.67 | V15: =T15+2*(W15-T15)/3+(2*Balance!H15-T15-W15) -> 323642.33 | W15: =IF(ISNUMBER('Quarter-End Anchors'!I15),'Quarter-End Anchors'!I15,2*Balance!H15-T15) -> 327253 | X15: =W15+(Z15-W15)/3+(2*Balance!I15-W15-Z15) -> 329765.67 | Y15: =W15+2*(Z15-W15)/3+(2*Balance!I15-W15-Z15) -> 332876.33 | Z15: =IF(ISNUMBER('Quarter-End Anchors'!J15),'Quarter-End Anchors'!J15,2*Balance!I15-W15) -> 336585 | AA15: =Z15+(AC15-Z15)/3+(2*Balance!J15-Z15-AC15) -> 336175.67 | AB15: =Z15+2*(AC15-Z15)/3+(2*Balance!J15-Z15-AC15) -> 337635.33 | AC15: =IF(ISNUMBER('Quarter-End Anchors'!K15),'Quarter-End Anchors'!K15,2*Balance!J15-Z15) -> 340964 | AD15: =AC15+(AF15-AC15)/3+(2*Balance!K15-AC15-AF15) -> 367136 | AE15: =AC15+2*(AF15-AC15)/3+(2*Balance!K15-AC15-AF15) -> 400225 | AF15: =IF(ISNUMBER('Quarter-End Anchors'!L15),'Quarter-End Anchors'!L15,2*Balance!K15-AC15) -> 440231 | AG15: =AF15*('Forecast Drivers'!C12/'Forecast Drivers'!B12) -> 440306 | AH15: =AG15*('Forecast Drivers'!D12/'Forecast Drivers'!C12) -> 440381 | AI15: =AH15*('Forecast Drivers'!E12/'Forecast Drivers'!D12) -> 440456.01 | AJ15: =AI15*('Forecast Drivers'!F12/'Forecast Drivers'!E12) -> 440531.01 | AK15: =AJ15*('Forecast Drivers'!G12/'Forecast Drivers'!F12) -> 440606.01 | AL15: =AK15*('Forecast Drivers'!H12/'Forecast Drivers'!G12) -> 440681.01 | AM15: =AL15*('Forecast Drivers'!I12/'Forecast Drivers'!H12) -> 440756.02 | AN15: =AM15*('Forecast Drivers'!J12/'Forecast Drivers'!I12) -> 440831.02 | ... AR15: =AQ15*('Forecast Drivers'!N12/'Forecast Drivers'!M12) -> 441131.03
A16: Securitized debt obligations | B16: =IF(ISNUMBER('Quarter-End Anchors'!B16),'Quarter-End Anchors'!B16,Balance!B16) -> 17251 | C16: =B16+(E16-B16)/3+(2*Balance!B16-B16-E16) -> 17251 | D16: =B16+2*(E16-B16)/3+(2*Balance!B16-B16-E16) -> 17251 | E16: =IF(ISNUMBER('Quarter-End Anchors'!C16),'Quarter-End Anchors'!C16,2*Balance!B16-B16) -> 17251 | F16: =E16+(H16-E16)/3+(2*Balance!C16-E16-H16) -> 17597.667 | G16: =E16+2*(H16-E16)/3+(2*Balance!C16-E16-H16) -> 17944.333 | H16: =IF(ISNUMBER('Quarter-End Anchors'!D16),'Quarter-End Anchors'!D16,2*Balance!C16-E16) -> 18291 | I16: =H16+(K16-H16)/3+(2*Balance!D16-H16-K16) -> 17863 | J16: =H16+2*(K16-H16)/3+(2*Balance!D16-H16-K16) -> 17435 | K16: =IF(ISNUMBER('Quarter-End Anchors'!E16),'Quarter-End Anchors'!E16,2*Balance!D16-H16) -> 17007 | L16: =K16+(N16-K16)/3+(2*Balance!E16-K16-N16) -> 18676.847 | M16: =K16+2*(N16-K16)/3+(2*Balance!E16-K16-N16) -> 18860.923 | N16: =IF(ISNUMBER('Quarter-End Anchors'!F16),'Quarter-End Anchors'!F16,2*Balance!E16-K16) -> 17559.23 | O16: =N16+(Q16-N16)/3+(2*Balance!F16-N16-Q16) -> 17988.604 | P16: =N16+2*(Q16-N16)/3+(2*Balance!F16-N16-Q16) -> 18050.687 | Q16: =IF(ISNUMBER('Quarter-End Anchors'!G16),'Quarter-End Anchors'!G16,2*Balance!F16-N16) -> 17745.478 | R16: =Q16+(T16-Q16)/3+(2*Balance!G16-Q16-T16) -> 17639.815 | S16: =Q16+2*(T16-Q16)/3+(2*Balance!G16-Q16-T16) -> 17399.169 | T16: =IF(ISNUMBER('Quarter-End Anchors'!H16),'Quarter-End Anchors'!H16,2*Balance!G16-Q16) -> 17023.538 | U16: =T16+(W16-T16)/3+(2*Balance!H16-T16-W16) -> 15228.46 | V16: =T16+2*(W16-T16)/3+(2*Balance!H16-T16-W16) -> 14935.461 | W16: =IF(ISNUMBER('Quarter-End Anchors'!I16),'Quarter-End Anchors'!I16,2*Balance!H16-T16) -> 16144.54 | X16: =W16+(Z16-W16)/3+(2*Balance!I16-W16-Z16) -> 14688.803 | Y16: =W16+2*(Z16-W16)/3+(2*Balance!I16-W16-Z16) -> 14192.131 | Z16: =IF(ISNUMBER('Quarter-End Anchors'!J16),'Quarter-End Anchors'!J16,2*Balance!I16-W16) -> 14654.525 | AA16: =Z16+(AC16-Z16)/3+(2*Balance!J16-Z16-AC16) -> 14017.746 | AB16: =Z16+2*(AC16-Z16)/3+(2*Balance!J16-Z16-AC16) -> 13412.611 | AC16: =IF(ISNUMBER('Quarter-End Anchors'!K16),'Quarter-End Anchors'!K16,2*Balance!J16-Z16) -> 12839.118 | AD16: =AC16+(AF16-AC16)/3+(2*Balance!K16-AC16-AF16) -> 11972.983 | AE16: =AC16+2*(AF16-AC16)/3+(2*Balance!K16-AC16-AF16) -> 12609.933 | AF16: =IF(ISNUMBER('Quarter-End Anchors'!L16),'Quarter-End Anchors'!L16,2*Balance!K16-AC16) -> 14749.967 | AG16: =AF16*(1-'Forecast Drivers'!$B$19) -> 14676.217 | AH16: =AG16*(1-'Forecast Drivers'!$B$19) -> 14602.836 | AI16: =AH16*(1-'Forecast Drivers'!$B$19) -> 14529.822 | AJ16: =AI16*(1-'Forecast Drivers'!$B$19) -> 14457.173 | AK16: =AJ16*(1-'Forecast Drivers'!$B$19) -> 14384.887 | AL16: =AK16*(1-'Forecast Drivers'!$B$19) -> 14312.962 | AM16: =AL16*(1-'Forecast Drivers'!$B$19) -> 14241.398 | AN16: =AM16*(1-'Forecast Drivers'!$B$19) -> 14170.191 | ... AR16: =AQ16*(1-'Forecast Drivers'!$B$19) -> 13888.905
A17: Senior and subordinated notes | B17: =IF(ISNUMBER('Quarter-End Anchors'!B17),'Quarter-End Anchors'!B17,Balance!B17) -> 30136 | C17: =B17+(E17-B17)/3+(2*Balance!B17-B17-E17) -> 30136 | D17: =B17+2*(E17-B17)/3+(2*Balance!B17-B17-E17) -> 30136 | E17: =IF(ISNUMBER('Quarter-End Anchors'!C17),'Quarter-End Anchors'!C17,2*Balance!B17-B17) -> 30136 | F17: =E17+(H17-E17)/3+(2*Balance!C17-E17-H17) -> 30152.667 | G17: =E17+2*(H17-E17)/3+(2*Balance!C17-E17-H17) -> 30169.333 | H17: =IF(ISNUMBER('Quarter-End Anchors'!D17),'Quarter-End Anchors'!D17,2*Balance!C17-E17) -> 30186 | I17: =H17+(K17-H17)/3+(2*Balance!D17-H17-K17) -> 31076.667 | J17: =H17+2*(K17-H17)/3+(2*Balance!D17-H17-K17) -> 31967.333 | K17: =IF(ISNUMBER('Quarter-End Anchors'!E17),'Quarter-End Anchors'!E17,2*Balance!D17-H17) -> 32858 | L17: =K17+(N17-K17)/3+(2*Balance!E17-K17-N17) -> 33080.82 | M17: =K17+2*(N17-K17)/3+(2*Balance!E17-K17-N17) -> 32714.41 | N17: =IF(ISNUMBER('Quarter-End Anchors'!F17),'Quarter-End Anchors'!F17,2*Balance!E17-K17) -> 31758.77 | O17: =N17+(Q17-N17)/3+(2*Balance!F17-N17-Q17) -> 32470.729 | P17: =N17+2*(Q17-N17)/3+(2*Balance!F17-N17-Q17) -> 32566.98 | Q17: =IF(ISNUMBER('Quarter-End Anchors'!G17),'Quarter-End Anchors'!G17,2*Balance!F17-N17) -> 32047.522 | R17: =Q17+(T17-Q17)/3+(2*Balance!G17-Q17-T17) -> 31128.518 | S17: =Q17+2*(T17-Q17)/3+(2*Balance!G17-Q17-T17) -> 30518.498 | T17: =IF(ISNUMBER('Quarter-End Anchors'!H17),'Quarter-End Anchors'!H17,2*Balance!G17-Q17) -> 30217.462 | U17: =T17+(W17-T17)/3+(2*Balance!H17-T17-W17) -> 32228.54 | V17: =T17+2*(W17-T17)/3+(2*Balance!H17-T17-W17) -> 33046.539 | W17: =IF(ISNUMBER('Quarter-End Anchors'!I17),'Quarter-End Anchors'!I17,2*Balance!H17-T17) -> 32671.46 | X17: =W17+(Z17-W17)/3+(2*Balance!I17-W17-Z17) -> 30654.53 | Y17: =W17+2*(Z17-W17)/3+(2*Balance!I17-W17-Z17) -> 29875.535 | Z17: =IF(ISNUMBER('Quarter-End Anchors'!J17),'Quarter-End Anchors'!J17,2*Balance!I17-W17) -> 30334.475 | AA17: =Z17+(AC17-Z17)/3+(2*Balance!J17-Z17-AC17) -> 31643.254 | AB17: =Z17+2*(AC17-Z17)/3+(2*Balance!J17-Z17-AC17) -> 30985.389 | AC17: =IF(ISNUMBER('Quarter-End Anchors'!K17),'Quarter-End Anchors'!K17,2*Balance!J17-Z17) -> 28360.882 | AD17: =AC17+(AF17-AC17)/3+(2*Balance!K17-AC17-AF17) -> 31507.684 | AE17: =AC17+2*(AF17-AC17)/3+(2*Balance!K17-AC17-AF17) -> 34445.401 | AF17: =IF(ISNUMBER('Quarter-End Anchors'!L17),'Quarter-End Anchors'!L17,2*Balance!K17-AC17) -> 37174.033 | AG17: =AF17 -> 37174.033 | AH17: =AG17 -> 37174.033 | AI17: =AH17 -> 37174.033 | AJ17: =AI17 -> 37174.033 | AK17: =AJ17 -> 37174.033 | AL17: =AK17 -> 37174.033 | AM17: =AL17 -> 37174.033 | AN17: =AM17 -> 37174.033 | ... AR17: =AQ17 -> 37174.033
