Workbook

Sheet Deposit Actuals
A2: Capital One deposit rate and balance actuals
A3: Monthly actuals from Jan-2024 through Jun-2026. Balances and monthly interest expense are in $ millions; rates are annualized.
A5: Period | B5: Start Month | C5: Through Month | D5: Checking Avg Balance | E5: Savings Avg Balance | F5: Time Deposits Avg Balance | G5: Total IB Avg Balance | H5: NIB Avg Balance | I5: Total Deposits Avg Balance | J5: IB Average Rate | K5: Total Deposit Cost
A6: 2024 | B6: 45322 | C6: 45657 | D6: =SUMIFS($F$13:$F$192,$D$13:$D$192,"Checking",$A$13:$A$192,">="&$B6,$A$13:$A$192,"<="&$C6)/COUNTIFS($D$13:$D$192,"Checking",$A$13:$A$192,">="&$B6,$A$13:$A$192,"<="&$C6) -> 34848.68 | E6: =SUMIFS($F$13:$F$192,$D$13:$D$192,"Savings",$A$13:$A$192,">="&$B6,$A$13:$A$192,"<="&$C6)/COUNTIFS($D$13:$D$192,"Savings",$A$13:$A$192,">="&$B6,$A$13:$A$192,"<="&$C6) -> 210768.01 | F6: =SUMIFS($F$13:$F$192,$D$13:$D$192,"Time deposits",$A$13:$A$192,">="&$B6,$A$13:$A$192,"<="&$C6)/COUNTIFS($D$13:$D$192,"Time deposits",$A$13:$A$192,">="&$B6,$A$13:$A$192,"<="&$C6) -> 78142.559 | G6: =SUMIFS($F$13:$F$192,$D$13:$D$192,"Total interest-bearing deposits",$A$13:$A$192,">="&$B6,$A$13:$A$192,"<="&$C6)/COUNTIFS($D$13:$D$192,"Total interest-bearing deposits",$A$13:$A$192,">="&$B6,$A$13:$A$192,"<="&$C6) -> 323759.25 | H6: =SUMIFS($F$13:$F$192,$D$13:$D$192,"Non-interest-bearing deposits",$A$13:$A$192,">="&$B6,$A$13:$A$192,"<="&$C6)/COUNTIFS($D$13:$D$192,"Non-interest-bearing deposits",$A$13:$A$192,">="&$B6,$A$13:$A$192,"<="&$C6) -> 26822.917 | I6: =SUMIFS($F$13:$F$192,$D$13:$D$192,"Total deposits",$A$13:$A$192,">="&$B6,$A$13:$A$192,"<="&$C6)/COUNTIFS($D$13:$D$192,"Total deposits",$A$13:$A$192,">="&$B6,$A$13:$A$192,"<="&$C6) -> 350582.17 | J6: =SUMIFS($H$13:$H$192,$D$13:$D$192,"Total interest-bearing deposits",$A$13:$A$192,">="&$B6,$A$13:$A$192,"<="&$C6)*12/SUMIFS($F$13:$F$192,$D$13:$D$192,"Total interest-bearing deposits",$A$13:$A$192,">="&$B6,$A$13:$A$192,"<="&$C6) -> 0.0354986 | K6: =SUMIFS($H$13:$H$192,$D$13:$D$192,"Total deposits",$A$13:$A$192,">="&$B6,$A$13:$A$192,"<="&$C6)*12/SUMIFS($F$13:$F$192,$D$13:$D$192,"Total deposits",$A$13:$A$192,">="&$B6,$A$13:$A$192,"<="&$C6) -> 0.032782614
A7: 2025 | B7: 45688 | C7: 46022 | D7: =SUMIFS($F$13:$F$192,$D$13:$D$192,"Checking",$A$13:$A$192,">="&$B7,$A$13:$A$192,"<="&$C7)/COUNTIFS($D$13:$D$192,"Checking",$A$13:$A$192,">="&$B7,$A$13:$A$192,"<="&$C7) -> 35892.669 | E7: =SUMIFS($F$13:$F$192,$D$13:$D$192,"Savings",$A$13:$A$192,">="&$B7,$A$13:$A$192,"<="&$C7)/COUNTIFS($D$13:$D$192,"Savings",$A$13:$A$192,">="&$B7,$A$13:$A$192,"<="&$C7) -> 273526.51 | F7: =SUMIFS($F$13:$F$192,$D$13:$D$192,"Time deposits",$A$13:$A$192,">="&$B7,$A$13:$A$192,"<="&$C7)/COUNTIFS($D$13:$D$192,"Time deposits",$A$13:$A$192,">="&$B7,$A$13:$A$192,"<="&$C7) -> 91919.117 | G7: =SUMIFS($F$13:$F$192,$D$13:$D$192,"Total interest-bearing deposits",$A$13:$A$192,">="&$B7,$A$13:$A$192,"<="&$C7)/COUNTIFS($D$13:$D$192,"Total interest-bearing deposits",$A$13:$A$192,">="&$B7,$A$13:$A$192,"<="&$C7) -> 401338.29 | H7: =SUMIFS($F$13:$F$192,$D$13:$D$192,"Non-interest-bearing deposits",$A$13:$A$192,">="&$B7,$A$13:$A$192,"<="&$C7)/COUNTIFS($D$13:$D$192,"Non-interest-bearing deposits",$A$13:$A$192,">="&$B7,$A$13:$A$192,"<="&$C7) -> 27477.875 | I7: =SUMIFS($F$13:$F$192,$D$13:$D$192,"Total deposits",$A$13:$A$192,">="&$B7,$A$13:$A$192,"<="&$C7)/COUNTIFS($D$13:$D$192,"Total deposits",$A$13:$A$192,">="&$B7,$A$13:$A$192,"<="&$C7) -> 428816.17 | J7: =SUMIFS($H$13:$H$192,$D$13:$D$192,"Total interest-bearing deposits",$A$13:$A$192,">="&$B7,$A$13:$A$192,"<="&$C7)*12/SUMIFS($F$13:$F$192,$D$13:$D$192,"Total interest-bearing deposits",$A$13:$A$192,">="&$B7,$A$13:$A$192,"<="&$C7) -> 0.032204752 | K7: =SUMIFS($H$13:$H$192,$D$13:$D$192,"Total deposits",$A$13:$A$192,">="&$B7,$A$13:$A$192,"<="&$C7)*12/SUMIFS($F$13:$F$192,$D$13:$D$192,"Total deposits",$A$13:$A$192,">="&$B7,$A$13:$A$192,"<="&$C7) -> 0.030141121
A8: H1 2026 | B8: 46053 | C8: 46203 | D8: =SUMIFS($F$13:$F$192,$D$13:$D$192,"Checking",$A$13:$A$192,">="&$B8,$A$13:$A$192,"<="&$C8)/COUNTIFS($D$13:$D$192,"Checking",$A$13:$A$192,">="&$B8,$A$13:$A$192,"<="&$C8) -> 39151.125 | E8: =SUMIFS($F$13:$F$192,$D$13:$D$192,"Savings",$A$13:$A$192,">="&$B8,$A$13:$A$192,"<="&$C8)/COUNTIFS($D$13:$D$192,"Savings",$A$13:$A$192,">="&$B8,$A$13:$A$192,"<="&$C8) -> 311465.18 | F8: =SUMIFS($F$13:$F$192,$D$13:$D$192,"Time deposits",$A$13:$A$192,">="&$B8,$A$13:$A$192,"<="&$C8)/COUNTIFS($D$13:$D$192,"Time deposits",$A$13:$A$192,">="&$B8,$A$13:$A$192,"<="&$C8) -> 103851.36 | G8: =SUMIFS($F$13:$F$192,$D$13:$D$192,"Total interest-bearing deposits",$A$13:$A$192,">="&$B8,$A$13:$A$192,"<="&$C8)/COUNTIFS($D$13:$D$192,"Total interest-bearing deposits",$A$13:$A$192,">="&$B8,$A$13:$A$192,"<="&$C8) -> 454467.67 | H8: =SUMIFS($F$13:$F$192,$D$13:$D$192,"Non-interest-bearing deposits",$A$13:$A$192,">="&$B8,$A$13:$A$192,"<="&$C8)/COUNTIFS($D$13:$D$192,"Non-interest-bearing deposits",$A$13:$A$192,">="&$B8,$A$13:$A$192,"<="&$C8) -> 28520.5 | I8: =SUMIFS($F$13:$F$192,$D$13:$D$192,"Total deposits",$A$13:$A$192,">="&$B8,$A$13:$A$192,"<="&$C8)/COUNTIFS($D$13:$D$192,"Total deposits",$A$13:$A$192,">="&$B8,$A$13:$A$192,"<="&$C8) -> 482988.17 | J8: =SUMIFS($H$13:$H$192,$D$13:$D$192,"Total interest-bearing deposits",$A$13:$A$192,">="&$B8,$A$13:$A$192,"<="&$C8)*12/SUMIFS($F$13:$F$192,$D$13:$D$192,"Total interest-bearing deposits",$A$13:$A$192,">="&$B8,$A$13:$A$192,"<="&$C8) -> 0.029595065 | K8: =SUMIFS($H$13:$H$192,$D$13:$D$192,"Total deposits",$A$13:$A$192,">="&$B8,$A$13:$A$192,"<="&$C8)*12/SUMIFS($F$13:$F$192,$D$13:$D$192,"Total deposits",$A$13:$A$192,">="&$B8,$A$13:$A$192,"<="&$C8) -> 0.027847473
A12: Month | B12: Year | C12: Quarter | D12: Deposit Type | E12: Interest Bearing | F12: Average Balance ($mm) | G12: Annualized Rate | H12: Monthly Interest Expense ($mm) | I12: Share of Total Deposits | J12: MoM Balance Change ($mm) | K12: MoM Balance Change (%) | L12: YoY Balance Change (%) | M12: Source Period | N12: Source Method | O12: Data Status
A13: 45322 | B13: 2024 | C13: Q1 | D13: Checking | E13: Yes | F13: ='Sources & Checks'!$C$61*'Sources & Checks'!$G$6 -> 35596.255 | G13: =H13*12/F13 -> 0.016638956 | H13: ='Sources & Checks'!$D$61*'Sources & Checks'!$D$6/'Sources & Checks'!$D$9 -> 49.357043 | I13: =F13/F18 -> 0.1032359 | J13: ="" | K13: ="" | L13: ="" | M13: 2024Q1 | N13: Quarter balance and expense mix applied to controlled totals | O13: Allocated from reported quarter actual
A14: 45322 | B14: 2024 | C14: Q1 | D14: Savings | E14: Yes | F14: ='Sources & Checks'!$C$61*'Sources & Checks'!$G$7 -> 205980.17 | G14: =H14*12/F14 -> 0.033436755 | H14: ='Sources & Checks'!$D$61*'Sources & Checks'!$D$7/'Sources & Checks'!$D$9 -> 573.94237 | I14: =F14/F18 -> 0.59738162 | J14: ="" | K14: ="" | L14: ="" | M14: 2024Q1 | N14: Quarter balance and expense mix applied to controlled totals | O14: Allocated from reported quarter actual
A15: 45322 | B15: 2024 | C15: Q1 | D15: Time deposits | E15: Yes | F15: ='Sources & Checks'!$C$61*'Sources & Checks'!$G$8 -> 75885.909 | G15: =H15*12/F15 -> 0.049730087 | H15: ='Sources & Checks'!$D$61*'Sources & Checks'!$D$8/'Sources & Checks'!$D$9 -> 314.4844 | I15: =F15/F18 -> 0.22008355 | J15: ="" | K15: ="" | L15: ="" | M15: 2024Q1 | N15: Quarter balance and expense mix applied to controlled totals | O15: Allocated from reported quarter actual
A16: 45322 | B16: 2024 | C16: Q1 | D16: Total interest-bearing deposits | E16: Yes | F16: =SUM(F13:F15) -> 317462.33 | G16: =H16*12/F16 -> 0.035448003 | H16: =SUM(H13:H15) -> 937.78382 | I16: =F16/F18 -> 0.92070107 | J16: ="" | K16: ="" | L16: ="" | M16: 2024Q1 | N16: Controlled monthly imputation | O16: Controlled monthly actual estimate
A17: 45322 | B17: 2024 | C17: Q1 | D17: Non-interest-bearing deposits | E17: No | F17: ='Sources & Checks'!$J$61 -> 27342.667 | G17: =0 -> 0 | H17: =0 -> 0 | I17: =F17/F18 -> 0.079298927 | J17: ="" | K17: ="" | L17: ="" | M17: 2024Q1 | N17: Quarterly average and EOP controlled interpolation | O17: Controlled monthly actual estimate
A18: 45322 | B18: 2024 | C18: Q1 | D18: Total deposits | E18: Mixed | F18: =SUM(F16,F17) -> 344805 | G18: =H18*12/F18 -> 0.032637015 | H18: =SUM(H16,H17) -> 937.78382 | I18: =F18/F18 -> 1 | J18: ="" | K18: ="" | L18: ="" | M18: 2024Q1 | N18: Interest-bearing plus non-interest-bearing deposits | O18: Calculated monthly total
A19: 45351 | B19: 2024 | C19: Q1 | D19: Checking | E19: Yes | F19: ='Sources & Checks'!$C$62*'Sources & Checks'!$G$6 -> 35323.468 | G19: =H19*12/F19 -> 0.016638956 | H19: ='Sources & Checks'!$D$62*'Sources & Checks'!$D$6/'Sources & Checks'!$D$9 -> 48.978801 | I19: =F19/F24 -> 0.10339897 | J19: =F19-F13 -> -272.7875 | K19: =IF(F13=0,"n.a.",F19/F13-1) -> -0.0076633763 | L19: ="" | M19: 2024Q1 | N19: Quarter balance and expense mix applied to controlled totals | O19: Allocated from reported quarter actual
A20: 45351 | B20: 2024 | C20: Q1 | D20: Savings | E20: Yes | F20: ='Sources & Checks'!$C$62*'Sources & Checks'!$G$7 -> 204401.67 | G20: =H20*12/F20 -> 0.033436755 | H20: ='Sources & Checks'!$D$62*'Sources & Checks'!$D$7/'Sources & Checks'!$D$9 -> 569.54404 | I20: =F20/F24 -> 0.59832525 | J20: =F20-F14 -> -1578.5036 | K20: =IF(F14=0,"n.a.",F20/F14-1) -> -0.0076633763 | L20: ="" | M20: 2024Q1 | N20: Quarter balance and expense mix applied to controlled totals | O20: Allocated from reported quarter actual
A21: 45351 | B21: 2024 | C21: Q1 | D21: Time deposits | E21: Yes | F21: ='Sources & Checks'!$C$62*'Sources & Checks'!$G$8 -> 75304.367 | G21: =H21*12/F21 -> 0.049730087 | H21: ='Sources & Checks'!$D$62*'Sources & Checks'!$D$8/'Sources & Checks'!$D$9 -> 312.07439 | I21: =F21/F24 -> 0.2204312 | J21: =F21-F15 -> -581.54228 | K21: =IF(F15=0,"n.a.",F21/F15-1) -> -0.0076633763 | L21: ="" | M21: 2024Q1 | N21: Quarter balance and expense mix applied to controlled totals | O21: Allocated from reported quarter actual
A22: 45351 | B22: 2024 | C22: Q1 | D22: Total interest-bearing deposits | E22: Yes | F22: =SUM(F19:F21) -> 315029.5 | G22: =H22*12/F22 -> 0.035448003 | H22: =SUM(H19:H21) -> 930.59723 | I22: =F22/F24 -> 0.92215542 | J22: =F22-F16 -> -2432.8333 | K22: =IF(F16=0,"n.a.",F22/F16-1) -> -0.0076633763 | L22: ="" | M22: 2024Q1 | N22: Controlled monthly imputation | O22: Controlled monthly actual estimate
A23: 45351 | B23: 2024 | C23: Q1 | D23: Non-interest-bearing deposits | E23: No | F23: ='Sources & Checks'!$J$62 -> 26593.5 | G23: =0 -> 0 | H23: =0 -> 0 | I23: =F23/F24 -> 0.077844583 | J23: =F23-F17 -> -749.16667 | K23: =IF(F17=0,"n.a.",F23/F17-1) -> -0.027399181 | L23: ="" | M23: 2024Q1 | N23: Quarterly average and EOP controlled interpolation | O23: Controlled monthly actual estimate
A24: 45351 | B24: 2024 | C24: Q1 | D24: Total deposits | E24: Mixed | F24: =SUM(F22,F23) -> 341623 | G24: =H24*12/F24 -> 0.032688568 | H24: =SUM(H22,H23) -> 930.59723 | I24: =F24/F24 -> 1 | J24: =F24-F18 -> -3182 | K24: =IF(F18=0,"n.a.",F24/F18-1) -> -0.0092284045 | L24: ="" | M24: 2024Q1 | N24: Interest-bearing plus non-interest-bearing deposits | O24: Calculated monthly total
A25: 45382 | B25: 2024 | C25: Q1 | D25: Checking | E25: Yes | F25: ='Sources & Checks'!$C$63*'Sources & Checks'!$G$6 -> 35817.745 | G25: =H25*12/F25 -> 0.016638956 | H25: ='Sources & Checks'!$D$63*'Sources & Checks'!$D$6/'Sources & Checks'!$D$9 -> 49.664155 | I25: =F25/F30 -> 0.10336743 | J25: =F25-F19 -> 494.27668 | K25: =IF(F19=0,"n.a.",F25/F19-1) -> 0.013992869 | L25: ="" | M25: 2024Q1 | N25: Quarter balance and expense mix applied to controlled totals | O25: Allocated from reported quarter actual
A26: 45382 | B26: 2024 | C26: Q1 | D26: Savings | E26: Yes | F26: ='Sources & Checks'!$C$63*'Sources & Checks'!$G$7 -> 207261.83 | G26: =H26*12/F26 -> 0.033436755 | H26: ='Sources & Checks'!$D$63*'Sources & Checks'!$D$7/'Sources & Checks'!$D$9 -> 577.51359 | I26: =F26/F30 -> 0.59814271 | J26: =F26-F20 -> 2860.1658 | K26: =IF(F20=0,"n.a.",F26/F20-1) -> 0.013992869 | L26: ="" | M26: 2024Q1 | N26: Quarter balance and expense mix applied to controlled totals | O26: Allocated from reported quarter actual
A27: 45382 | B27: 2024 | C27: Q1 | D27: Time deposits | E27: Yes | F27: ='Sources & Checks'!$C$63*'Sources & Checks'!$G$8 -> 76358.091 | G27: =H27*12/F27 -> 0.049730087 | H27: ='Sources & Checks'!$D$63*'Sources & Checks'!$D$8/'Sources & Checks'!$D$9 -> 316.44121 | I27: =F27/F30 -> 0.22036395 | J27: =F27-F21 -> 1053.7242 | K27: =IF(F21=0,"n.a.",F27/F21-1) -> 0.013992869 | L27: ="" | M27: 2024Q1 | N27: Quarter balance and expense mix applied to controlled totals | O27: Allocated from reported quarter actual
A28: 45382 | B28: 2024 | C28: Q1 | D28: Total interest-bearing deposits | E28: Yes | F28: =SUM(F25:F27) -> 319437.67 | G28: =H28*12/F28 -> 0.035448003 | H28: =SUM(H25:H27) -> 943.61895 | I28: =F28/F30 -> 0.92187408 | J28: =F28-F22 -> 4408.1667 | K28: =IF(F22=0,"n.a.",F28/F22-1) -> 0.013992869 | L28: ="" | M28: 2024Q1 | N28: Controlled monthly imputation | O28: Controlled monthly actual estimate
A29: 45382 | B29: 2024 | C29: Q1 | D29: Non-interest-bearing deposits | E29: No | F29: ='Sources & Checks'!$J$63 -> 27071.333 | G29: =0 -> 0 | H29: =0 -> 0 | I29: =F29/F30 -> 0.078125917 | J29: =F29-F23 -> 477.83333 | K29: =IF(F23=0,"n.a.",F29/F23-1) -> 0.01796805 | L29: ="" | M29: 2024Q1 | N29: Quarterly average and EOP controlled interpolation | O29: Controlled monthly actual estimate
A30: 45382 | B30: 2024 | C30: Q1 | D30: Total deposits | E30: Mixed | F30: =SUM(F28,F29) -> 346509 | G30: =H30*12/F30 -> 0.032678595 | H30: =SUM(H28,H29) -> 943.61895 | I30: =F30/F30 -> 1 | J30: =F30-F24 -> 4886 | K30: =IF(F24=0,"n.a.",F30/F24-1) -> 0.014302316 | L30: ="" | M30: 2024Q1 | N30: Interest-bearing plus non-interest-bearing deposits | O30: Calculated monthly total
A31: 45412 | B31: 2024 | C31: Q2 | D31: Checking | E31: Yes | F31: ='Sources & Checks'!$C$64*'Sources & Checks'!$G$11 -> 34815.922 | G31: =H31*12/F31 -> 0.015858564 | H31: ='Sources & Checks'!$D$64*'Sources & Checks'!$D$11/'Sources & Checks'!$D$14 -> 46.010876 | I31: =F31/F36 -> 0.099664754 | J31: =F31-F25 -> -1001.8228 | K31: =IF(F25=0,"n.a.",F31/F25-1) -> -0.027970014 | L31: ="" | M31: 2024Q2 | N31: Quarter balance and expense mix applied to controlled totals | O31: Allocated from reported quarter actual
A32: 45412 | B32: 2024 | C32: Q2 | D32: Savings | E32: Yes | F32: ='Sources & Checks'!$C$64*'Sources & Checks'!$G$12 -> 208597.86 | G32: =H32*12/F32 -> 0.033622865 | H32: ='Sources & Checks'!$D$64*'Sources & Checks'!$D$12/'Sources & Checks'!$D$14 -> 584.47149 | I32: =F32/F36 -> 0.59713642 | J32: =F32-F26 -> 1336.0336 | K32: =IF(F26=0,"n.a.",F32/F26-1) -> 0.0064461152 | L32: ="" | M32: 2024Q2 | N32: Quarter balance and expense mix applied to controlled totals | O32: Allocated from reported quarter actual
A33: 45412 | B33: 2024 | C33: Q2 | D33: Time deposits | E33: Yes | F33: ='Sources & Checks'!$C$64*'Sources & Checks'!$G$13 -> 78805.547 | G33: =H33*12/F33 -> 0.049906762 | H33: ='Sources & Checks'!$D$64*'Sources & Checks'!$D$13/'Sources & Checks'!$D$14 -> 327.74414 | I33: =F33/F36 -> 0.22559033 | J33: =F33-F27 -> 2447.4558 | K33: =IF(F27=0,"n.a.",F33/F27-1) -> 0.032052344 | L33: ="" | M33: 2024Q2 | N33: Quarter balance and expense mix applied to controlled totals | O33: Allocated from reported quarter actual
A34: 45412 | B34: 2024 | C34: Q2 | D34: Total interest-bearing deposits | E34: Yes | F34: =SUM(F31:F33) -> 322219.33 | G34: =H34*12/F34 -> 0.035685997 | H34: =SUM(H31:H33) -> 958.22651 | I34: =F34/F36 -> 0.92239151 | J34: =F34-F28 -> 2781.6667 | K34: =IF(F28=0,"n.a.",F34/F28-1) -> 0.0087080108 | L34: ="" | M34: 2024Q2 | N34: Controlled monthly imputation | O34: Controlled monthly actual estimate
A35: 45412 | B35: 2024 | C35: Q2 | D35: Non-interest-bearing deposits | E35: No | F35: ='Sources & Checks'!$J$64 -> 27111 | G35: =0 -> 0 | H35: =0 -> 0 | I35: =F35/F36 -> 0.077608491 | J35: =F35-F29 -> 39.666667 | K35: =IF(F29=0,"n.a.",F35/F29-1) -> 0.0014652646 | L35: ="" | M35: 2024Q2 | N35: Quarterly average and EOP controlled interpolation | O35: Controlled monthly actual estimate
A36: 45412 | B36: 2024 | C36: Q2 | D36: Total deposits | E36: Mixed | F36: =SUM(F34,F35) -> 349330.33 | G36: =H36*12/F36 -> 0.03291646 | H36: =SUM(H34,H35) -> 958.22651 | I36: =F36/F36 -> 1 | J36: =F36-F30 -> 2821.3333 | K36: =IF(F30=0,"n.a.",F36/F30-1) -> 0.0081421647 | L36: ="" | M36: 2024Q2 | N36: Interest-bearing plus non-interest-bearing deposits | O36: Calculated monthly total
A37: 45443 | B37: 2024 | C37: Q2 | D37: Checking | E37: Yes | F37: ='Sources & Checks'!$C$65*'Sources & Checks'!$G$11 -> 34713.076 | G37: =H37*12/F37 -> 0.015858564 | H37: ='Sources & Checks'!$D$65*'Sources & Checks'!$D$11/'Sources & Checks'!$D$14 -> 45.87496 | I37: =F37/F42 -> 0.099816045 | J37: =F37-F31 -> -102.84595 | K37: =IF(F31=0,"n.a.",F37/F31-1) -> -0.002953992 | L37: ="" | M37: 2024Q2 | N37: Quarter balance and expense mix applied to controlled totals | O37: Allocated from reported quarter actual
A38: 45443 | B38: 2024 | C38: Q2 | D38: Savings | E38: Yes | F38: ='Sources & Checks'!$C$65*'Sources & Checks'!$G$12 -> 207981.67 | G38: =H38*12/F38 -> 0.033622865 | H38: ='Sources & Checks'!$D$65*'Sources & Checks'!$D$12/'Sources & Checks'!$D$14 -> 582.74497 | I38: =F38/F42 -> 0.59804287 | J38: =F38-F32 -> -616.19642 | K38: =IF(F32=0,"n.a.",F38/F32-1) -> -0.002953992 | L38: ="" | M38: 2024Q2 | N38: Quarter balance and expense mix applied to controlled totals | O38: Allocated from reported quarter actual
A39: 45443 | B39: 2024 | C39: Q2 | D39: Time deposits | E39: Yes | F39: ='Sources & Checks'!$C$65*'Sources & Checks'!$G$13 -> 78572.756 | G39: =H39*12/F39 -> 0.049906762 | H39: ='Sources & Checks'!$D$65*'Sources & Checks'!$D$13/'Sources & Checks'!$D$14 -> 326.77599 | I39: =F39/F42 -> 0.22593278 | J39: =F39-F33 -> -232.79095 | K39: =IF(F33=0,"n.a.",F39/F33-1) -> -0.002953992 | L39: ="" | M39: 2024Q2 | N39: Quarter balance and expense mix applied to controlled totals | O39: Allocated from reported quarter actual
A40: 45443 | B40: 2024 | C40: Q2 | D40: Total interest-bearing deposits | E40: Yes | F40: =SUM(F37:F39) -> 321267.5 | G40: =H40*12/F40 -> 0.035685997 | H40: =SUM(H37:H39) -> 955.39591 | I40: =F40/F42 -> 0.9237917 | J40: =F40-F34 -> -951.83333 | K40: =IF(F34=0,"n.a.",F40/F34-1) -> -0.002953992 | L40: ="" | M40: 2024Q2 | N40: Controlled monthly imputation | O40: Controlled monthly actual estimate
A41: 45443 | B41: 2024 | C41: Q2 | D41: Non-interest-bearing deposits | E41: No | F41: ='Sources & Checks'!$J$65 -> 26503 | G41: =0 -> 0 | H41: =0 -> 0 | I41: =F41/F42 -> 0.076208304 | J41: =F41-F35 -> -608 | K41: =IF(F35=0,"n.a.",F41/F35-1) -> -0.022426321 | L41: ="" | M41: 2024Q2 | N41: Quarterly average and EOP controlled interpolation | O41: Controlled monthly actual estimate
A42: 45443 | B42: 2024 | C42: Q2 | D42: Total deposits | E42: Mixed | F42: =SUM(F40,F41) -> 347770.5 | G42: =H42*12/F42 -> 0.032966427 | H42: =SUM(H40,H41) -> 955.39591 | I42: =F42/F42 -> 1 | J42: =F42-F36 -> -1559.8333 | K42: =IF(F36=0,"n.a.",F42/F36-1) -> -0.0044652101 | L42: ="" | M42: 2024Q2 | N42: Interest-bearing plus non-interest-bearing deposits | O42: Calculated monthly total
A43: 45473 | B43: 2024 | C43: Q2 | D43: Checking | E43: Yes | F43: ='Sources & Checks'!$C$66*'Sources & Checks'!$G$11 -> 34894.078 | G43: =H43*12/F43 -> 0.015858564 | H43: ='Sources & Checks'!$D$66*'Sources & Checks'!$D$11/'Sources & Checks'!$D$14 -> 46.114164 | I43: =F43/F48 -> 0.0997984 | J43: =F43-F37 -> 181.0024 | K43: =IF(F37=0,"n.a.",F43/F37-1) -> 0.0052142425 | L43: ="" | M43: 2024Q2 | N43: Quarter balance and expense mix applied to controlled totals | O43: Allocated from reported quarter actual
A44: 45473 | B44: 2024 | C44: Q2 | D44: Savings | E44: Yes | F44: ='Sources & Checks'!$C$66*'Sources & Checks'!$G$12 -> 209066.14 | G44: =H44*12/F44 -> 0.033622865 | H44: ='Sources & Checks'!$D$66*'Sources & Checks'!$D$12/'Sources & Checks'!$D$14 -> 585.78354 | I44: =F44/F48 -> 0.59793716 | J44: =F44-F38 -> 1084.4669 | K44: =IF(F38=0,"n.a.",F44/F38-1) -> 0.0052142425 | L44: ="" | M44: 2024Q2 | N44: Quarter balance and expense mix applied to controlled totals | O44: Allocated from reported quarter actual
A45: 45473 | B45: 2024 | C45: Q2 | D45: Time deposits | E45: Yes | F45: ='Sources & Checks'!$C$66*'Sources & Checks'!$G$13 -> 78982.453 | G45: =H45*12/F45 -> 0.049906762 | H45: ='Sources & Checks'!$D$66*'Sources & Checks'!$D$13/'Sources & Checks'!$D$14 -> 328.47987 | I45: =F45/F48 -> 0.22589284 | J45: =F45-F39 -> 409.69741 | K45: =IF(F39=0,"n.a.",F45/F39-1) -> 0.0052142425 | L45: ="" | M45: 2024Q2 | N45: Quarter balance and expense mix applied to controlled totals | O45: Allocated from reported quarter actual
...

Sheet Sources & Checks
A2: Deposit rate and balance sources
A3: Quarterly average balances and interest expense come from Capital One filings. Monthly interest-bearing totals come from the controlled workbook.
A5: Source Period | B5: Deposit Type | C5: Reported Average Balance ($mm) | D5: Reported Interest Expense ($mm) | E5: Reported Average Rate | F5: Effective Rate | G5: Share of Interest-Bearing Balance | H5: Disclosure Basis | N5: Month | O5: IB Balance Difference | P5: IB Expense Difference | Q5: NIB Quarter-End Difference | R5: Status
A6: 2024Q1 | B6: Checking | C6: 35707 | D6: 148 | E6: 0.0166 | F6: =D6*4/C6 -> 0.016579382 | G6: =C6/C9 -> 0.11212749 | H6: Reported three-month average | N6: ='Deposit Actuals'!A16 -> 45322 | O6: =ROUND('Deposit Actuals'!F16-C61,2) -> 0 | P6: =ROUND('Deposit Actuals'!H16-D61,2) -> 0 | Q6: ="" | R6: =IF(AND(ABS(O6)<0.01,ABS(P6)<0.01),"OK","Review") -> OK
A7: 2024Q1 | B7: Savings | C7: 206621 | D7: 1721 | E7: 0.0333 | F7: =D7*4/C7 -> 0.033317039 | G7: =C7/C9 -> 0.64883341 | H7: Reported three-month average | N7: ='Deposit Actuals'!A22 -> 45351 | O7: =ROUND('Deposit Actuals'!F22-C62,2) -> 0 | P7: =ROUND('Deposit Actuals'!H22-D62,2) -> 0 | Q7: ="" | R7: =IF(AND(ABS(O7)<0.01,ABS(P7)<0.01),"OK","Review") -> OK
A8: 2024Q1 | B8: Time deposits | C8: 76122 | D8: 943 | E8: 0.0495 | F8: =D8*4/C8 -> 0.049552035 | G8: =C8/C9 -> 0.2390391 | H8: Reported three-month average | N8: ='Deposit Actuals'!A28 -> 45382 | O8: =ROUND('Deposit Actuals'!F28-C63,2) -> 0 | P8: =ROUND('Deposit Actuals'!H28-D63,2) -> 0 | Q8: =ROUND(I63-G63,2) -> 0 | R8: =IF(AND(ABS(O8)<0.01,ABS(P8)<0.01,ABS(Q8)<0.01),"OK","Review") -> OK
A9: 2024Q1 | B9: Total interest-bearing deposits | C9: 318450 | D9: 2812 | E9: 0.0353 | F9: =D9*4/C9 -> 0.035321087 | G9: =1 -> 1 | H9: Reported three-month average | N9: ='Deposit Actuals'!A34 -> 45412 | O9: =ROUND('Deposit Actuals'!F34-C64,2) -> 0 | P9: =ROUND('Deposit Actuals'!H34-D64,2) -> 0 | Q9: ="" | R9: =IF(AND(ABS(O9)<0.01,ABS(P9)<0.01),"OK","Review") -> OK
A10: 2024Q1 | B10: Non-interest-bearing deposits | C10: 27207 | D10: 0 | E10: 0 | F10: =0 -> 0 | G10: ="" | H10: Reported three-month average | N10: ='Deposit Actuals'!A40 -> 45443 | O10: =ROUND('Deposit Actuals'!F40-C65,2) -> 0 | P10: =ROUND('Deposit Actuals'!H40-D65,2) -> 0 | Q10: ="" | R10: =IF(AND(ABS(O10)<0.01,ABS(P10)<0.01),"OK","Review") -> OK
A11: 2024Q2 | B11: Checking | C11: 34855 | D11: 138 | E11: 0.0158 | F11: =D11*4/C11 -> 0.015837039 | G11: =C11/C14 -> 0.10805038 | H11: Reported three-month average | N11: ='Deposit Actuals'!A46 -> 45473 | O11: =ROUND('Deposit Actuals'!F46-C66,2) -> 0 | P11: =ROUND('Deposit Actuals'!H46-D66,2) -> 0 | Q11: =ROUND(I66-G66,2) -> 0 | R11: =IF(AND(ABS(O11)<0.01,ABS(P11)<0.01,ABS(Q11)<0.01),"OK","Review") -> OK
A12: 2024Q2 | B12: Savings | C12: 208832 | D12: 1753 | E12: 0.0336 | F12: =D12*4/C12 -> 0.03357723 | G12: =C12/C14 -> 0.64737849 | H12: Reported three-month average | N12: ='Deposit Actuals'!A52 -> 45504 | O12: =ROUND('Deposit Actuals'!F52-C67,2) -> 0 | P12: =ROUND('Deposit Actuals'!H52-D67,2) -> 0 | Q12: ="" | R12: =IF(AND(ABS(O12)<0.01,ABS(P12)<0.01),"OK","Review") -> OK
A13: 2024Q2 | B13: Time deposits | C13: 78894 | D13: 983 | E13: 0.0499 | F13: =D13*4/C13 -> 0.049839025 | G13: =C13/C14 -> 0.24457113 | H13: Reported three-month average | N13: ='Deposit Actuals'!A58 -> 45535 | O13: =ROUND('Deposit Actuals'!F58-C68,2) -> 0 | P13: =ROUND('Deposit Actuals'!H58-D68,2) -> 0 | Q13: ="" | R13: =IF(AND(ABS(O13)<0.01,ABS(P13)<0.01),"OK","Review") -> OK
A14: 2024Q2 | B14: Total interest-bearing deposits | C14: 322581 | D14: 2874 | E14: 0.0356 | F14: =D14*4/C14 -> 0.035637561 | G14: =1 -> 1 | H14: Reported three-month average | N14: ='Deposit Actuals'!A64 -> 45565 | O14: =ROUND('Deposit Actuals'!F64-C69,2) -> 0 | P14: =ROUND('Deposit Actuals'!H64-D69,2) -> 0 | Q14: =ROUND(I69-G69,2) -> 0 | R14: =IF(AND(ABS(O14)<0.01,ABS(P14)<0.01,ABS(Q14)<0.01),"OK","Review") -> OK
A15: 2024Q2 | B15: Non-interest-bearing deposits | C15: 26907 | D15: 0 | E15: 0 | F15: =0 -> 0 | G15: ="" | H15: Reported three-month average | N15: ='Deposit Actuals'!A70 -> 45596 | O15: =ROUND('Deposit Actuals'!F70-C70,2) -> 0 | P15: =ROUND('Deposit Actuals'!H70-D70,2) -> 0 | Q15: ="" | R15: =IF(AND(ABS(O15)<0.01,ABS(P15)<0.01),"OK","Review") -> OK
A16: 2024Q3 | B16: Checking | C16: 33936 | D16: 135 | E16: 0.0159 | F16: =D16*4/C16 -> 0.015912306 | G16: =C16/C19 -> 0.10457645 | H16: Reported three-month average | N16: ='Deposit Actuals'!A76 -> 45626 | O16: =ROUND('Deposit Actuals'!F76-C71,2) -> 0 | P16: =ROUND('Deposit Actuals'!H76-D71,2) -> 0 | Q16: ="" | R16: =IF(AND(ABS(O16)<0.01,ABS(P16)<0.01),"OK","Review") -> OK
A17: 2024Q3 | B17: Savings | C17: 211608 | D17: 1825 | E17: 0.0345 | F17: =D17*4/C17 -> 0.034497751 | G17: =C17/C19 -> 0.65208669 | H17: Reported three-month average | N17: ='Deposit Actuals'!A82 -> 45657 | O17: =ROUND('Deposit Actuals'!F82-C72,2) -> 0 | P17: =ROUND('Deposit Actuals'!H82-D72,2) -> 0 | Q17: =ROUND(I72-G72,2) -> 0 | R17: =IF(AND(ABS(O17)<0.01,ABS(P17)<0.01,ABS(Q17)<0.01),"OK","Review") -> OK
A18: 2024Q3 | B18: Time deposits | C18: 78965 | D18: 985 | E18: 0.0499 | F18: =D18*4/C18 -> 0.049895523 | G18: =C18/C19 -> 0.24333686 | H18: Reported three-month average | N18: ='Deposit Actuals'!A88 -> 45688 | O18: =ROUND('Deposit Actuals'!F88-C73,2) -> 0 | P18: =ROUND('Deposit Actuals'!H88-D73,2) -> 0 | Q18: ="" | R18: =IF(AND(ABS(O18)<0.01,ABS(P18)<0.01),"OK","Review") -> OK
A19: 2024Q3 | B19: Total interest-bearing deposits | C19: 324509 | D19: 2945 | E19: 0.0363 | F19: =D19*4/C19 -> 0.036300996 | G19: =1 -> 1 | H19: Reported three-month average | N19: ='Deposit Actuals'!A94 -> 45716 | O19: =ROUND('Deposit Actuals'!F94-C74,2) -> 0 | P19: =ROUND('Deposit Actuals'!H94-D74,2) -> 0 | Q19: ="" | R19: =IF(AND(ABS(O19)<0.01,ABS(P19)<0.01),"OK","Review") -> OK
A20: 2024Q3 | B20: Non-interest-bearing deposits | C20: 26616 | D20: 0 | E20: 0 | F20: =0 -> 0 | G20: ="" | H20: Reported three-month average | N20: ='Deposit Actuals'!A100 -> 45747 | O20: =ROUND('Deposit Actuals'!F100-C75,2) -> 0 | P20: =ROUND('Deposit Actuals'!H100-D75,2) -> 0 | Q20: =ROUND(I75-G75,2) -> 0 | R20: =IF(AND(ABS(O20)<0.01,ABS(P20)<0.01,ABS(Q20)<0.01),"OK","Review") -> OK
A21: 2024Q4 | B21: Checking | C21: 35129 | D21: 123 | E21: 0.014005523 | F21: =D21*4/C21 -> 0.014005523 | G21: =C21/C24 -> 0.10593149 | H21: Derived Q4 = full year less nine months | N21: ='Deposit Actuals'!A106 -> 45777 | O21: =ROUND('Deposit Actuals'!F106-C76,2) -> 0 | P21: =ROUND('Deposit Actuals'!H106-D76,2) -> 0 | Q21: ="" | R21: =IF(AND(ABS(O21)<0.01,ABS(P21)<0.01),"OK","Review") -> OK
A22: 2024Q4 | B22: Savings | C22: 217390 | D22: 1784 | E22: 0.032825797 | F22: =D22*4/C22 -> 0.032825797 | G22: =C22/C24 -> 0.65553947 | H22: Derived Q4 = full year less nine months | N22: ='Deposit Actuals'!A112 -> 45808 | O22: =ROUND('Deposit Actuals'!F112-C77,2) -> 0 | P22: =ROUND('Deposit Actuals'!H112-D77,2) -> 0 | Q22: ="" | R22: =IF(AND(ABS(O22)<0.01,ABS(P22)<0.01),"OK","Review") -> OK
A23: 2024Q4 | B23: Time deposits | C23: 79101 | D23: 955 | E23: 0.048292689 | F23: =D23*4/C23 -> 0.048292689 | G23: =C23/C24 -> 0.23852904 | H23: Derived Q4 = full year less nine months | N23: ='Deposit Actuals'!A118 -> 45838 | O23: =ROUND('Deposit Actuals'!F118-C78,2) -> 0 | P23: =ROUND('Deposit Actuals'!H118-D78,2) -> 0 | Q23: =ROUND(I78-G78,2) -> 0 | R23: =IF(AND(ABS(O23)<0.01,ABS(P23)<0.01,ABS(Q23)<0.01),"OK","Review") -> OK
A24: 2024Q4 | B24: Total interest-bearing deposits | C24: 331620 | D24: 2862 | E24: 0.03452144 | F24: =D24*4/C24 -> 0.03452144 | G24: =1 -> 1 | H24: Derived Q4 = full year less nine months | N24: ='Deposit Actuals'!A124 -> 45869 | O24: =ROUND('Deposit Actuals'!F124-C79,2) -> 0 | P24: =ROUND('Deposit Actuals'!H124-D79,2) -> 0 | Q24: ="" | R24: =IF(AND(ABS(O24)<0.01,ABS(P24)<0.01),"OK","Review") -> OK
A25: 2024Q4 | B25: Non-interest-bearing deposits | C25: 26757 | D25: 0 | E25: 0 | F25: =0 -> 0 | G25: ="" | H25: Derived Q4 = full year less nine months | N25: ='Deposit Actuals'!A130 -> 45900 | O25: =ROUND('Deposit Actuals'!F130-C80,2) -> 0 | P25: =ROUND('Deposit Actuals'!H130-D80,2) -> 0 | Q25: ="" | R25: =IF(AND(ABS(O25)<0.01,ABS(P25)<0.01),"OK","Review") -> OK
A26: 2025Q1 | B26: Checking | C26: 36285 | D26: 119 | E26: 0.0131 | F26: =D26*4/C26 -> 0.013118368 | G26: =C26/C29 -> 0.10740291 | H26: Reported three-month average | N26: ='Deposit Actuals'!A136 -> 45930 | O26: =ROUND('Deposit Actuals'!F136-C81,2) -> 0 | P26: =ROUND('Deposit Actuals'!H136-D81,2) -> 0 | Q26: =ROUND(I81-G81,2) -> 0 | R26: =IF(AND(ABS(O26)<0.01,ABS(P26)<0.01,ABS(Q26)<0.01),"OK","Review") -> OK
A27: 2025Q1 | B27: Savings | C27: 227780 | D27: 1768 | E27: 0.0311 | F27: =D27*4/C27 -> 0.031047502 | G27: =C27/C29 -> 0.67422448 | H27: Reported three-month average | N27: ='Deposit Actuals'!A142 -> 45961 | O27: =ROUND('Deposit Actuals'!F142-C82,2) -> 0 | P27: =ROUND('Deposit Actuals'!H142-D82,2) -> 0 | Q27: ="" | R27: =IF(AND(ABS(O27)<0.01,ABS(P27)<0.01),"OK","Review") -> OK
A28: 2025Q1 | B28: Time deposits | C28: 73775 | D28: 828 | E28: 0.0449 | F28: =D28*4/C28 -> 0.044893257 | G28: =C28/C29 -> 0.2183726 | H28: Reported three-month average | N28: ='Deposit Actuals'!A148 -> 45991 | O28: =ROUND('Deposit Actuals'!F148-C83,2) -> 0 | P28: =ROUND('Deposit Actuals'!H148-D83,2) -> 0 | Q28: ="" | R28: =IF(AND(ABS(O28)<0.01,ABS(P28)<0.01),"OK","Review") -> OK
A29: 2025Q1 | B29: Total interest-bearing deposits | C29: 337840 | D29: 2715 | E29: 0.0322 | F29: =D29*4/C29 -> 0.032145394 | G29: =1 -> 1 | H29: Reported three-month average | N29: ='Deposit Actuals'!A154 -> 46022 | O29: =ROUND('Deposit Actuals'!F154-C84,2) -> 0 | P29: =ROUND('Deposit Actuals'!H154-D84,2) -> 0 | Q29: =ROUND(I84-G84,2) -> 0 | R29: =IF(AND(ABS(O29)<0.01,ABS(P29)<0.01,ABS(Q29)<0.01),"OK","Review") -> OK
A30: 2025Q1 | B30: Non-interest-bearing deposits | C30: 26238 | D30: 0 | E30: 0 | F30: =0 -> 0 | G30: ="" | H30: Reported three-month average | N30: ='Deposit Actuals'!A160 -> 46053 | O30: =ROUND('Deposit Actuals'!F160-C85,2) -> 0 | P30: =ROUND('Deposit Actuals'!H160-D85,2) -> 0 | Q30: ="" | R30: =IF(AND(ABS(O30)<0.01,ABS(P30)<0.01),"OK","Review") -> OK
A31: 2025Q2 | B31: Checking | C31: 35776 | D31: 108 | E31: 0.012 | F31: =D31*4/C31 -> 0.012075134 | G31: =C31/C34 -> 0.092411253 | H31: Reported three-month average | N31: ='Deposit Actuals'!A166 -> 46081 | O31: =ROUND('Deposit Actuals'!F166-C86,2) -> 0 | P31: =ROUND('Deposit Actuals'!H166-D86,2) -> 0 | Q31: ="" | R31: =IF(AND(ABS(O31)<0.01,ABS(P31)<0.01),"OK","Review") -> OK
A32: 2025Q2 | B32: Savings | C32: 265622 | D32: 2064 | E32: 0.0311 | F32: =D32*4/C32 -> 0.031081763 | G32: =C32/C34 -> 0.68611532 | H32: Reported three-month average | N32: ='Deposit Actuals'!A172 -> 46112 | O32: =ROUND('Deposit Actuals'!F172-C87,2) -> 0 | P32: =ROUND('Deposit Actuals'!H172-D87,2) -> 0 | Q32: =ROUND(I87-G87,2) -> 0 | R32: =IF(AND(ABS(O32)<0.01,ABS(P32)<0.01,ABS(Q32)<0.01),"OK","Review") -> OK
A33: 2025Q2 | B33: Time deposits | C33: 85741 | D33: 948 | E33: 0.0442 | F33: =D33*4/C33 -> 0.044226216 | G33: =C33/C34 -> 0.22147342 | H33: Reported three-month average | N33: ='Deposit Actuals'!A178 -> 46142 | O33: =ROUND('Deposit Actuals'!F178-C88,2) -> 0 | P33: =ROUND('Deposit Actuals'!H178-D88,2) -> 0 | Q33: ="" | R33: =IF(AND(ABS(O33)<0.01,ABS(P33)<0.01),"OK","Review") -> OK
A34: 2025Q2 | B34: Total interest-bearing deposits | C34: 387139 | D34: 3120 | E34: 0.0322 | F34: =D34*4/C34 -> 0.032236484 | G34: =1 -> 1 | H34: Reported three-month average | N34: ='Deposit Actuals'!A184 -> 46173 | O34: =ROUND('Deposit Actuals'!F184-C89,2) -> 0 | P34: =ROUND('Deposit Actuals'!H184-D89,2) -> 0 | Q34: ="" | R34: =IF(AND(ABS(O34)<0.01,ABS(P34)<0.01),"OK","Review") -> OK
A35: 2025Q2 | B35: Non-interest-bearing deposits | C35: 27429 | D35: 0 | E35: 0 | F35: =0 -> 0 | G35: ="" | H35: Reported three-month average | N35: ='Deposit Actuals'!A190 -> 46203 | O35: =ROUND('Deposit Actuals'!F190-C90,2) -> 0 | P35: =ROUND('Deposit Actuals'!H190-D90,2) -> 0 | Q35: =ROUND(I90-G90,2) -> 0 | R35: =IF(AND(ABS(O35)<0.01,ABS(P35)<0.01,ABS(Q35)<0.01),"OK","Review") -> OK
A36: 2025Q3 | B36: Checking | C36: 35419 | D36: 107 | E36: 0.0121 | F36: =D36*4/C36 -> 0.01208391 | G36: =C36/C39 -> 0.080584355 | H36: Reported three-month average
A37: 2025Q3 | B37: Savings | C37: 300386 | D37: 2355 | E37: 0.0314 | F37: =D37*4/C37 -> 0.031359651 | G37: =C37/C39 -> 0.68343014 | H37: Reported three-month average
A38: 2025Q3 | B38: Time deposits | C38: 103722 | D38: 1135 | E38: 0.0438 | F38: =D38*4/C38 -> 0.043770849 | G38: =C38/C39 -> 0.2359855 | H38: Reported three-month average
A39: 2025Q3 | B39: Total interest-bearing deposits | C39: 439527 | D39: 3597 | E39: 0.0327 | F39: =D39*4/C39 -> 0.03273519 | G39: =1 -> 1 | H39: Reported three-month average | N39: Source Period | O39: Product Balance Difference | P39: Product Interest Difference | Q39: Status
A40: 2025Q3 | B40: Non-interest-bearing deposits | C40: 27753 | D40: 0 | E40: 0 | F40: =0 -> 0 | G40: ="" | H40: Reported three-month average | N40: ="2024Q1" -> 2024Q1 | O40: =ROUND(SUM(C6,C7,C8)-C9,2) -> 0 | P40: =ROUND(SUM(D6,D7,D8)-D9,2) -> 0 | Q40: =IF(AND(ABS(O40)<0.01,ABS(P40)<0.01),"OK","Review") -> OK
A41: 2025Q4 | B41: Checking | C41: 36304 | D41: 99 | E41: 0.010907889 | F41: =D41*4/C41 -> 0.010907889 | G41: =C41/C44 -> 0.081910955 | H41: Derived Q4 = full year less nine months | N41: ="2024Q2" -> 2024Q2 | O41: =ROUND(SUM(C11,C12,C13)-C14,2) -> 0 | P41: =ROUND(SUM(D11,D12,D13)-D14,2) -> 0 | Q41: =IF(AND(ABS(O41)<0.01,ABS(P41)<0.01),"OK","Review") -> OK
A42: 2025Q4 | B42: Savings | C42: 301934 | D42: 2314 | E42: 0.030655706 | F42: =D42*4/C42 -> 0.030655706 | G42: =C42/C44 -> 0.68123904 | H42: Derived Q4 = full year less nine months | N42: ="2024Q3" -> 2024Q3 | O42: =ROUND(SUM(C16,C17,C18)-C19,2) -> 0 | P42: =ROUND(SUM(D16,D17,D18)-D19,2) -> 0 | Q42: =IF(AND(ABS(O42)<0.01,ABS(P42)<0.01),"OK","Review") -> OK
...
